Workbook

Sheet lake_michigan
A1: 0.01 | B1: 0.58 | C1: 0.56 | D1: 12.5 | E1: 44 | F1: 0.65604442 | H1: =+SUM(H10:H824) -> 249.7187 | J1: Best Fit | K1: 0.58 | L1: 13.7483
D2: 2.7 | E2: <- this was 2.5 | H2: goal | L2: 2.7207897
B3: 2 | C3: 2 | D3: 1.05 | F3: 1.7070066 | K3: 2 | L3: 1.1139459
B4: reference | D4: 0.5 | F4: other power law
F5: change 2.4 to 0 to remove nonlinearity
F6: change 2 to 1.7 to change power law | M6: =+SUM($M10:$M5000) -> 111324755
I7: Cumulative | J7: Cumulative | K7: Cumulative | L7: Cumulative
I8: RMS | J8: chop&swell | K8: chop | L8: swell | M8: RMS | N8: chop | O8: swell
B9: chop&swell | C9: Model | D9: Nonlinear | E9: RMS | F9: chop | G9: swell | I9: =+M9 -> 111324755 | J9: =+$N9+$O9 -> 205833319 | K9: =+$N9 -> 95648470 | L9: =+$O9 -> 110184849 | M9: =+SUM($M10:$M5000) -> 111324755 | N9: =+SUM(N10:N5000) -> 95648470 | O9: =+SUM(O10:O5000) -> 110184849
A10: 0.01 | B10: =+$J10/$J$9 -> 0.98957889 | C10: =2*($A10/$C$1*$D10)*BESSELK(2*($A10/$C$1*$D10),1) -> 0.99748633 | D10: =+(1-$D$2*$A10/$D$1*(1-$D$3*$A10/$D$1))^$D$4 -> 0.99892032 | E10: =+$I10/$I$9 -> 0.99641277 | F10: =+$K10/$K$9 -> 0.99452844 | G10: =+$L10/$L$9 -> 0.98528231 | H10: =+ABS(LN($C10/$E10)) -> 0.0010768465 | I10: =+$I9-$M10 -> 110925407 | J10: =+$J9-$N10-$O10 -> 203688307 | K10: =+$K9-$N10 -> 95125124 | L10: =+$L9-$O10 -> 108563183 | M10: 399348 | N10: 523346 | O10: 1621666
A11: =+$A10+$A$1 -> 0.02 | B11: =+$J11/$J$9 -> 0.96894607 | C11: =2*($A11/$C$1*$D11)*BESSELK(2*($A11/$C$1*$D11),1) -> 0.99172031 | D11: =+(1-$D$2*$A11/$D$1*(1-$D$3*$A11/$D$1))^$D$4 -> 0.9978413 | E11: =+$I11/$I$9 -> 0.98994215 | F11: =+$K11/$K$9 -> 0.98359282 | G11: =+$L11/$L$9 -> 0.95623162 | H11: =+ABS(LN($C11/$E11)) -> 0.0017946222 | I11: =+$I10-$M11 -> 110205067 | J11: =+$J10-$N11-$O11 -> 199441385 | K11: =+$K10-$N11 -> 94079148 | L11: =+$L10-$O11 -> 105362237 | M11: 720340 | N11: 1045976 | O11: 3200946
A12: =+$A11+$A$1 -> 0.03 | B12: =+$J12/$J$9 -> 0.93990705 | C12: =2*($A12/$C$1*$D12)*BESSELK(2*($A12/$C$1*$D12),1) -> 0.98370224 | D12: =+(1-$D$2*$A12/$D$1*(1-$D$3*$A12/$D$1))^$D$4 -> 0.99676293 | E12: =+$I12/$I$9 -> 0.98098552 | F12: =+$K12/$K$9 -> 0.96560315 | G12: =+$L12/$L$9 -> 0.91760096 | H12: =+ABS(LN($C12/$E12)) -> 0.0027655442 | I12: =+$I11-$M12 -> 109207973 | J12: =+$J11-$N12-$O12 -> 193464187 | K12: =+$K11-$N12 -> 92358464 | L12: =+$L11-$O12 -> 101105723 | M12: 997094 | N12: 1720684 | O12: 4256514
A13: =+$A12+$A$1 -> 0.04 | B13: =+$J13/$J$9 -> 0.90784112 | C13: =2*($A13/$C$1*$D13)*BESSELK(2*($A13/$C$1*$D13),1) -> 0.97395519 | D13: =+(1-$D$2*$A13/$D$1*(1-$D$3*$A13/$D$1))^$D$4 -> 0.99568521 | E13: =+$I13/$I$9 -> 0.97046331 | F13: =+$K13/$K$9 -> 0.94588804 | G13: =+$L13/$L$9 -> 0.87481361 | H13: =+ABS(LN($C13/$E13)) -> 0.0035917058 | I13: =+$I12-$M13 -> 108036590 | J13: =+$J12-$N13-$O13 -> 186863950 | K13: =+$K12-$N13 -> 90472744 | L13: =+$L12-$O13 -> 96391206 | M13: 1171383 | N13: 1885720 | O13: 4714517
A14: =+$A13+$A$1 -> 0.05 | B14: =+$J14/$J$9 -> 0.87795897 | C14: =2*($A14/$C$1*$D14)*BESSELK(2*($A14/$C$1*$D14),1) -> 0.96283511 | D14: =+(1-$D$2*$A14/$D$1*(1-$D$3*$A14/$D$1))^$D$4 -> 0.99460814 | E14: =+$I14/$I$9 -> 0.95928073 | F14: =+$K14/$K$9 -> 0.93097902 | G14: =+$L14/$L$9 -> 0.83193371 | H14: =+ABS(LN($C14/$E14)) -> 0.0036984137 | I14: =+$I13-$M14 -> 106791692 | J14: =+$J13-$N14-$O14 -> 180713209 | K14: =+$K13-$N14 -> 89046719 | L14: =+$L13-$O14 -> 91666490 | M14: 1244898 | N14: 1426025 | O14: 4724716
A15: =+$A14+$A$1 -> 0.06 | B15: =+$J15/$J$9 -> 0.84951686 | C15: =2*($A15/$C$1*$D15)*BESSELK(2*($A15/$C$1*$D15),1) -> 0.95060785 | D15: =+(1-$D$2*$A15/$D$1*(1-$D$3*$A15/$D$1))^$D$4 -> 0.99353174 | E15: =+$I15/$I$9 -> 0.94772977 | F15: =+$K15/$K$9 -> 0.91683099 | G15: =+$L15/$L$9 -> 0.79108329 | H15: =+ABS(LN($C15/$E15)) -> 0.0030322214 | I15: =+$I14-$M15 -> 105505784 | J15: =+$J14-$N15-$O15 -> 174858874 | K15: =+$K14-$N15 -> 87693481 | L15: =+$L14-$O15 -> 87165393 | M15: 1285908 | N15: 1353238 | O15: 4501097
A16: =+$A15+$A$1 -> 0.07 | B16: =+$J16/$J$9 -> 0.822661 | C16: =2*($A16/$C$1*$D16)*BESSELK(2*($A16/$C$1*$D16),1) -> 0.93748224 | D16: =+(1-$D$2*$A16/$D$1*(1-$D$3*$A16/$D$1))^$D$4 -> 0.992456 | E16: =+$I16/$I$9 -> 0.93569837 | F16: =+$K16/$K$9 -> 0.90349582 | G16: =+$L16/$L$9 -> 0.75249049 | H16: =+ABS(LN($C16/$E16)) -> 0.0019046378 | I16: =+$I15-$M16 -> 104166392 | J16: =+$J15-$N16-$O16 -> 169331044 | K16: =+$K15-$N16 -> 86417993 | L16: =+$L15-$O16 -> 82913051 | M16: 1339392 | N16: 1275488 | O16: 4252342
A17: =+$A16+$A$1 -> 0.08 | B17: =+$J17/$J$9 -> 0.79637998 | C17: =2*($A17/$C$1*$D17)*BESSELK(2*($A17/$C$1*$D17),1) -> 0.92362751 | D17: =+(1-$D$2*$A17/$D$1*(1-$D$3*$A17/$D$1))^$D$4 -> 0.99138092 | E17: =+$I17/$I$9 -> 0.92313247 | F17: =+$K17/$K$9 -> 0.88866368 | G17: =+$L17/$L$9 -> 0.71627101 | H17: =+ABS(LN($C17/$E17)) -> 0.00053611682 | I17: =+$I16-$M17 -> 102767496 | J17: =+$J16-$N17-$O17 -> 163921534 | K17: =+$K16-$N17 -> 84999321 | L17: =+$L16-$O17 -> 78922213 | M17: 1398896 | N17: 1418672 | O17: 3990838
A18: =+$A17+$A$1 -> 0.09 | B18: =+$J18/$J$9 -> 0.7713126 | C18: =2*($A18/$C$1*$D18)*BESSELK(2*($A18/$C$1*$D18),1) -> 0.90918378 | D18: =+(1-$D$2*$A18/$D$1*(1-$D$3*$A18/$D$1))^$D$4 -> 0.9903065 | E18: =+$I18/$I$9 -> 0.90993265 | F18: =+$K18/$K$9 -> 0.87375608 | G18: =+$L18/$L$9 -> 0.6823842 | H18: =+ABS(LN($C18/$E18)) -> 0.00082332938 | I18: =+$I17-$M18 -> 101298029 | J18: =+$J17-$N18-$O18 -> 158761832 | K18: =+$K17-$N18 -> 83573432 | L18: =+$L17-$O18 -> 75188400 | M18: 1469467 | N18: 1425889 | O18: 3733813
A19: =+$A18+$A$1 -> 0.1 | B19: =+$J19/$J$9 -> 0.74707396 | C19: =2*($A19/$C$1*$D19)*BESSELK(2*($A19/$C$1*$D19),1) -> 0.8942688 | D19: =+(1-$D$2*$A19/$D$1*(1-$D$3*$A19/$D$1))^$D$4 -> 0.98923275 | E19: =+$I19/$I$9 -> 0.89612803 | F19: =+$K19/$K$9 -> 0.85809463 | G19: =+$L19/$L$9 -> 0.65069993 | H19: =+ABS(LN($C19/$E19)) -> 0.0020768857 | I19: =+$I18-$M19 -> 99761233 | J19: =+$J18-$N19-$O19 -> 153772712 | K19: =+$K18-$N19 -> 82075438 | L19: =+$L18-$O19 -> 71697274 | M19: 1536796 | N19: 1497994 | O19: 3491126
A20: =+$A19+$A$1 -> 0.11 | B20: =+$J20/$J$9 -> 0.72360231 | C20: =2*($A20/$C$1*$D20)*BESSELK(2*($A20/$C$1*$D20),1) -> 0.87898263 | D20: =+(1-$D$2*$A20/$D$1*(1-$D$3*$A20/$D$1))^$D$4 -> 0.98815967 | E20: =+$I20/$I$9 -> 0.88178777 | F20: =+$K20/$K$9 -> 0.84180934 | G20: =+$L20/$L$9 -> 0.62099001 | H20: =+ABS(LN($C20/$E20)) -> 0.0031862711 | I20: =+$I19-$M20 -> 98164808 | J20: =+$J19-$N20-$O20 -> 148941465 | K20: =+$K19-$N20 -> 80517775 | L20: =+$L19-$O20 -> 68423690 | M20: 1596425 | N20: 1557663 | O20: 3273584
A21: =+$A20+$A$1 -> 0.12 | B21: =+$J21/$J$9 -> 0.70119738 | C21: =2*($A21/$C$1*$D21)*BESSELK(2*($A21/$C$1*$D21),1) -> 0.863411 | D21: =+(1-$D$2*$A21/$D$1*(1-$D$3*$A21/$D$1))^$D$4 -> 0.98708727 | E21: =+$I21/$I$9 -> 0.86709797 | F21: =+$K21/$K$9 -> 0.82571854 | G21: =+$L21/$L$9 -> 0.59310396 | H21: =+ABS(LN($C21/$E21)) -> 0.0042611443 | I21: =+$I20-$M21 -> 96529469 | J21: =+$J20-$N21-$O21 -> 144329785 | K21: =+$K20-$N21 -> 78978715 | L21: =+$L20-$O21 -> 65351070 | M21: 1635339 | N21: 1539060 | O21: 3072620
A22: =+$A21+$A$1 -> 0.13 | B22: =+$J22/$J$9 -> 0.679618 | C22: =2*($A22/$C$1*$D22)*BESSELK(2*($A22/$C$1*$D22),1) -> 0.84762783 | D22: =+(1-$D$2*$A22/$D$1*(1-$D$3*$A22/$D$1))^$D$4 -> 0.98601553 | E22: =+$I22/$I$9 -> 0.85220144 | F22: =+$K22/$K$9 -> 0.80950893 | G22: =+$L22/$L$9 -> 0.56686322 | H22: =+ABS(LN($C22/$E22)) -> 0.0053812758 | I22: =+$I21-$M22 -> 94871117 | J22: =+$J21-$N22-$O22 -> 139888029 | K22: =+$K21-$N22 -> 77428291 | L22: =+$L21-$O22 -> 62459738 | M22: 1658352 | N22: 1550424 | O22: 2891332
... A37: =+$A36+$A$1 -> 0.28 | B37: =+$J37/$J$9 -> 0.42303864 | C37: =2*($A37/$C$1*$D37)*BESSELK(2*($A37/$C$1*$D37),1) -> 0.61460918 | D37: =+(1-$D$2*$A37/$D$1*(1-$D$3*$A37/$D$1))^$D$4 -> 0.9700219 | E37: =+$I37/$I$9 -> 0.62063594 | F37: =+$K37/$K$9 -> 0.5728624 | G37: =+$L37/$L$9 -> 0.29298071 | H37: =+ABS(LN($C37/$E37)) -> 0.0097580743 | I37: =+$I36-$M37 -> 69092144 | J37: =+$J36-$N37-$O37 -> 87075447 | K37: =+$K36-$N37 -> 54793412 | L37: =+$L36-$O37 -> 32282035 | M37: 2961416 | N37: 2563147 | O37: 2619464
A38: =+$A37+$A$1 -> 0.29 | B38: =+$J38/$J$9 -> 0.42303864 | C38: =2*($A38/$C$1*$D38)*BESSELK(2*($A38/$C$1*$D38),1) -> 0.60040658 | D38: =+(1-$D$2*$A38/$D$1*(1-$D$3*$A38/$D$1))^$D$4 -> 0.96896125 | E38: =+$I38/$I$9 -> 0.62063594 | F38: =+$K38/$K$9 -> 0.5728624 | G38: =+$L38/$L$9 -> 0.29298071 | H38: =+ABS(LN($C38/$E38)) -> 0.033137596 | I38: =+$I37-$M38 -> 69092144 | J38: =+$J37-$N38-$O38 -> 87075447 | K38: =+$K37-$N38 -> 54793412 | L38: =+$L37-$O38 -> 32282035
A39: =+$A38+$A$1 -> 0.3 | B39: =+$J39/$J$9 -> 0.41094517 | C39: =2*($A39/$C$1*$D39)*BESSELK(2*($A39/$C$1*$D39),1) -> 0.58643923 | D39: =+(1-$D$2*$A39/$D$1*(1-$D$3*$A39/$D$1))^$D$4 -> 0.96790132 | E39: =+$I39/$I$9 -> 0.60767191 | F39: =+$K39/$K$9 -> 0.55965006 | G39: =+$L39/$L$9 -> 0.2818585 | H39: =+ABS(LN($C39/$E39)) -> 0.03556608 | I39: =+$I38-$M39 -> 67648927 | J39: =+$J38-$N39-$O39 -> 84586208 | K39: =+$K38-$N39 -> 53529672 | L39: =+$L38-$O39 -> 31056536 | M39: 1443217 | N39: 1263740 | O39: 1225499
A40: =+$A39+$A$1 -> 0.31 | B40: =+$J40/$J$9 -> 0.39919492 | C40: =2*($A40/$C$1*$D40)*BESSELK(2*($A40/$C$1*$D40),1) -> 0.57271186 | D40: =+(1-$D$2*$A40/$D$1*(1-$D$3*$A40/$D$1))^$D$4 -> 0.9668421 | E40: =+$I40/$I$9 -> 0.59493968 | F40: =+$K40/$K$9 -> 0.54663859 | G40: =+$L40/$L$9 -> 0.27120309 | H40: =+ABS(LN($C40/$E40)) -> 0.038077291 | I40: =+$I39-$M40 -> 66231514 | J40: =+$J39-$N40-$O40 -> 82167616 | K40: =+$K39-$N40 -> 52285145 | L40: =+$L39-$O40 -> 29882471 | M40: 1417413 | N40: 1244527 | O40: 1174065
A41: =+$A40+$A$1 -> 0.32 | B41: =+$J41/$J$9 -> 0.38779467 | C41: =2*($A41/$C$1*$D41)*BESSELK(2*($A41/$C$1*$D41),1) -> 0.55922822 | D41: =+(1-$D$2*$A41/$D$1*(1-$D$3*$A41/$D$1))^$D$4 -> 0.96578359 | E41: =+$I41/$I$9 -> 0.58241939 | F41: =+$K41/$K$9 -> 0.53387347 | G41: =+$L41/$L$9 -> 0.26098762 | H41: =+ABS(LN($C41/$E41)) -> 0.040633136 | I41: =+$I40-$M41 -> 64837696 | J41: =+$J40-$N41-$O41 -> 79821063 | K41: =+$K40-$N41 -> 51064181 | L41: =+$L40-$O41 -> 28756882 | M41: 1393818 | N41: 1220964 | O41: 1125589
A42: =+$A41+$A$1 -> 0.33 | B42: =+$J42/$J$9 -> 0.37675713 | C42: =2*($A42/$C$1*$D42)*BESSELK(2*($A42/$C$1*$D42),1) -> 0.54599113 | D42: =+(1-$D$2*$A42/$D$1*(1-$D$3*$A42/$D$1))^$D$4 -> 0.96472581 | E42: =+$I42/$I$9 -> 0.5701639 | F42: =+$K42/$K$9 -> 0.52137644 | G42: =+$L42/$L$9 -> 0.25121704 | H42: =+ABS(LN($C42/$E42)) -> 0.04332115 | I42: =+$I41-$M42 -> 63473357 | J42: =+$J41-$N42-$O42 -> 77549171 | K42: =+$K41-$N42 -> 49868859 | L42: =+$L41-$O42 -> 27680312 | M42: 1364339 | N42: 1195322 | O42: 1076570
A43: =+$A42+$A$1 -> 0.34 | B43: =+$J43/$J$9 -> 0.36608544 | C43: =2*($A43/$C$1*$D43)*BESSELK(2*($A43/$C$1*$D43),1) -> 0.53300258 | D43: =+(1-$D$2*$A43/$D$1*(1-$D$3*$A43/$D$1))^$D$4 -> 0.96366874 | E43: =+$I43/$I$9 -> 0.55814144 | F43: =+$K43/$K$9 -> 0.5092434 | G43: =+$L43/$L$9 -> 0.24181392 | H43: =+ABS(LN($C43/$E43)) -> 0.046086146 | I43: =+$I42-$M43 -> 62134959 | J43: =+$J42-$N43-$O43 -> 75352582 | K43: =+$K42-$N43 -> 48708352 | L43: =+$L42-$O43 -> 26644230 | M43: 1338398 | N43: 1160507 | O43: 1036082
A44: =+$A43+$A$1 -> 0.35 | B44: =+$J44/$J$9 -> 0.35577948 | C44: =2*($A44/$C$1*$D44)*BESSELK(2*($A44/$C$1*$D44),1) -> 0.52026385 | D44: =+(1-$D$2*$A44/$D$1*(1-$D$3*$A44/$D$1))^$D$4 -> 0.9626124 | E44: =+$I44/$I$9 -> 0.54634009 | F44: =+$K44/$K$9 -> 0.4974817 | G44: =+$L44/$L$9 -> 0.23277165 | H44: =+ABS(LN($C44/$E44)) -> 0.048905584 | I44: =+$I43-$M44 -> 60821177 | J44: =+$J43-$N44-$O44 -> 73231272 | K44: =+$K43-$N44 -> 47583363 | L44: =+$L43-$O44 -> 25647909 | M44: 1313782 | N44: 1124989 | O44: 996321
A45: =+$A44+$A$1 -> 0.36 | B45: =+$J45/$J$9 -> 0.34581446 | C45: =2*($A45/$C$1*$D45)*BESSELK(2*($A45/$C$1*$D45),1) -> 0.50777554 | D45: =+(1-$D$2*$A45/$D$1*(1-$D$3*$A45/$D$1))^$D$4 -> 0.96155679 | E45: =+$I45/$I$9 -> 0.53476385 | F45: =+$K45/$K$9 -> 0.48601674 | G45: =+$L45/$L$9 -> 0.22410867 | H45: =+ABS(LN($C45/$E45)) -> 0.051785747 | I45: =+$I44-$M45 -> 59532455 | J45: =+$J44-$N45-$O45 -> 71180138 | K45: =+$K44-$N45 -> 46486758 | L45: =+$L44-$O45 -> 24693380 | M45: 1288722 | N45: 1096605 | O45: 954529
A46: =+$A45+$A$1 -> 0.37 | B46: =+$J46/$J$9 -> 0.33613747 | C46: =2*($A46/$C$1*$D46)*BESSELK(2*($A46/$C$1*$D46),1) -> 0.4955377 | D46: =+(1-$D$2*$A46/$D$1*(1-$D$3*$A46/$D$1))^$D$4 -> 0.96050191 | E46: =+$I46/$I$9 -> 0.52341535 | F46: =+$K46/$K$9 -> 0.47477123 | G46: =+$L46/$L$9 -> 0.21579328 | H46: =+ABS(LN($C46/$E46)) -> 0.05473189 | I46: =+$I45-$M46 -> 58269086 | J46: =+$J45-$N46-$O46 -> 69188292 | K46: =+$K45-$N46 -> 45411142 | L46: =+$L45-$O46 -> 23777150 | M46: 1263369 | N46: 1075616 | O46: 916230
A47: =+$A46+$A$1 -> 0.38 | B47: =+$J47/$J$9 -> 0.32669465 | C47: =2*($A47/$C$1*$D47)*BESSELK(2*($A47/$C$1*$D47),1) -> 0.48354982 | D47: =+(1-$D$2*$A47/$D$1*(1-$D$3*$A47/$D$1))^$D$4 -> 0.95944775 | E47: =+$I47/$I$9 -> 0.51228412 | F47: =+$K47/$K$9 -> 0.4636621 | G47: =+$L47/$L$9 -> 0.20779694 | H47: =+ABS(LN($C47/$E47)) -> 0.057725048 | I47: =+$I46-$M47 -> 57029904 | J47: =+$J46-$N47-$O47 -> 67244644 | K47: =+$K46-$N47 -> 44348570 | L47: =+$L46-$O47 -> 22896074 | M47: 1239182 | N47: 1062572 | O47: 881076
A48: =+$A47+$A$1 -> 0.39 | B48: =+$J48/$J$9 -> 0.31749577 | C48: =2*($A48/$C$1*$D48)*BESSELK(2*($A48/$C$1*$D48),1) -> 0.47181093 | D48: =+(1-$D$2*$A48/$D$1*(1-$D$3*$A48/$D$1))^$D$4 -> 0.95839434 | E48: =+$I48/$I$9 -> 0.50138709 | F48: =+$K48/$K$9 -> 0.45272589 | G48: =+$L48/$L$9 -> 0.20010619 | H48: =+ABS(LN($C48/$E48)) -> 0.060800097 | I48: =+$I47-$M48 -> 55816795 | J48: =+$J47-$N48-$O48 -> 65351209 | K48: =+$K47-$N48 -> 43302539 | L48: =+$L47-$O48 -> 22048670 | M48: 1213109 | N48: 1046031 | O48: 847404
A49: =+$A48+$A$1 -> 0.4 | B49: =+$J49/$J$9 -> 0.30854653 | C49: =2*($A49/$C$1*$D49)*BESSELK(2*($A49/$C$1*$D49),1) -> 0.46031968 | D49: =+(1-$D$2*$A49/$D$1*(1-$D$3*$A49/$D$1))^$D$4 -> 0.95734165 | E49: =+$I49/$I$9 -> 0.49069549 | F49: =+$K49/$K$9 -> 0.44196548 | G49: =+$L49/$L$9 -> 0.19272917 | H49: =+ABS(LN($C49/$E49)) -> 0.063902551 | I49: =+$I48-$M49 -> 54626555 | J49: =+$J48-$N49-$O49 -> 63509157 | K49: =+$K48-$N49 -> 42273322 | L49: =+$L48-$O49 -> 21235835 | M49: 1190240 | N49: 1029217 | O49: 812835
A50: =+$A49+$A$1 -> 0.41 | B50: =+$J50/$J$9 -> 0.29984653 | C50: =2*($A50/$C$1*$D50)*BESSELK(2*($A50/$C$1*$D50),1) -> 0.4490743 | D50: =+(1-$D$2*$A50/$D$1*(1-$D$3*$A50/$D$1))^$D$4 -> 0.95628971 | E50: =+$I50/$I$9 -> 0.4802275 | F50: =+$K50/$K$9 -> 0.43142615 | G50: =+$L50/$L$9 -> 0.18562585 | H50: =+ABS(LN($C50/$E50)) -> 0.067071602 | I50: =+$I49-$M50 -> 53461209 | J50: =+$J49-$N50-$O50 -> 61718407 | K50: =+$K49-$N50 -> 41265251 | L50: =+$L49-$O50 -> 20453156 | M50: 1165346 | N50: 1008071 | O50: 782679
... A66: =+$A65+$A$1 -> 0.57 | B66: =+$J66/$J$9 -> 0.18726664 | C66: =2*($A66/$C$1*$D66)*BESSELK(2*($A66/$C$1*$D66),1) -> 0.30026464 | D66: =+(1-$D$2*$A66/$D$1*(1-$D$3*$A66/$D$1))^$D$4 -> 0.93956106 | E66: =+$I66/$I$9 -> 0.33290064 | F66: =+$K66/$K$9 -> 0.28950456 | G66: =+$L66/$L$9 -> 0.098516694 | H66: =+ABS(LN($C66/$E66)) -> 0.10317984 | I66: =+$I65-$M66 -> 37060082 | J66: =+$J65-$N66-$O66 -> 38545715 | K66: =+$K65-$N66 -> 27690668 | L66: =+$L65-$O66 -> 10855047 | M66: 801129 | N66: 629483 | O66: 409889
A67: =+$A66+$A$1 -> 0.58 | B67: =+$J67/$J$9 -> 0.18726664 | C67: =2*($A67/$C$1*$D67)*BESSELK(2*($A67/$C$1*$D67),1) -> 0.29273116 | D67: =+(1-$D$2*$A67/$D$1*(1-$D$3*$A67/$D$1))^$D$4 -> 0.93852205 | E67: =+$I67/$I$9 -> 0.33290064 | F67: =+$K67/$K$9 -> 0.28950456 | G67: =+$L67/$L$9 -> 0.098516694 | H67: =+ABS(LN($C67/$E67)) -> 0.12858941 | I67: =+$I66-$M67 -> 37060082 | J67: =+$J66-$N67-$O67 -> 38545715 | K67: =+$K66-$N67 -> 27690668 | L67: =+$L66-$O67 -> 10855047
A68: =+$A67+$A$1 -> 0.59 | B68: =+$J68/$J$9 -> 0.18235277 | C68: =2*($A68/$C$1*$D68)*BESSELK(2*($A68/$C$1*$D68),1) -> 0.28538287 | D68: =+(1-$D$2*$A68/$D$1*(1-$D$3*$A68/$D$1))^$D$4 -> 0.93748383 | E68: =+$I68/$I$9 -> 0.32585336 | F68: =+$K68/$K$9 -> 0.2830634 | G68: =+$L68/$L$9 -> 0.094928605 | H68: =+ABS(LN($C68/$E68)) -> 0.1326158 | I68: =+$I67-$M68 -> 36275546 | J68: =+$J67-$N68-$O68 -> 37534275 | K68: =+$K67-$N68 -> 27074581 | L68: =+$L67-$O68 -> 10459694 | M68: 784536 | N68: 616087 | O68: 395353
A69: =+$A68+$A$1 -> 0.6 | B69: =+$J69/$J$9 -> 0.17755946 | C69: =2*($A69/$C$1*$D69)*BESSELK(2*($A69/$C$1*$D69),1) -> 0.27821592 | D69: =+(1-$D$2*$A69/$D$1*(1-$D$3*$A69/$D$1))^$D$4 -> 0.93644639 | E69: =+$I69/$I$9 -> 0.31897115 | F69: =+$K69/$K$9 -> 0.27674311 | G69: =+$L69/$L$9 -> 0.091460823 | H69: =+ABS(LN($C69/$E69)) -> 0.13670316 | I69: =+$I68-$M69 -> 35509385 | J69: =+$J68-$N69-$O69 -> 36547652 | K69: =+$K68-$N69 -> 26470055 | L69: =+$L68-$O69 -> 10077597 | M69: 766161 | N69: 604526 | O69: 382097
...

Sheet east_coast
A1: 0.01 | C1: 0.81 | D1: 26 | G1: 10000 | H1: 123.03273 | I1: 96.436022 | K1: =+SUM(K10:K1494) -> 301.59731 | M1: Best fit | N1: 0.8 | O1: 25.13286
C2: 1 | D2: 2.7 | G2: 2.5 | N2: 1 | O2: 2.6020874
C3: 2 | D3: 1.05 | G3: 2 | N3: 2 | O3: 0.97
D4: 0.5 | G4: =+$G$2*$G$3 -> 5
P6: =+SUM($P10:$P5000) -> 30296756
L7: Cumulative | M7: Cumulative | N7: Cumulative | O7: Cumulative
L8: RMS | M8: chop&swell | N8: chop | O8: swell | P8: RMS | Q8: chop | R8: swell
B9: chop&swell | C9: Model | D9: Nonlinear | G9: Nonlinear | H9: RMS | I9: chop | J9: swell | L9: =+P9 -> 30296756 | M9: =+$Q9+$R9 -> 45108100 | N9: =+$Q9 -> 14811357 | O9: =+$R9 -> 30296743 | P9: =+SUM($P10:$P5000) -> 30296756 | Q9: =+SUM(Q10:Q5000) -> 14811357 | R9: =+SUM(R10:R5000) -> 30296743
A10: 0.01 | B10: =+$M10/$M$9 -> 0.97989006 | C10: =2*(($A10/$C$1*$D10)^$C$2)^$C$3*BESSELK(2*(($A10/$C$1)*$D10)^$C$2,$C$3)/FACT($C$3-1) -> 0.99984785 | D10: =+(1-$D$2*$A10/$D$1*(1-$D$3*$A10/$D$1))^$D$4 -> 0.99948084 | G10: =+SQRT(1-$G$2*$A10/$G$1*(1-$G$3*$A10/$G$1)) -> 0.99999875 | H10: =+$L10/$L$9 -> 0.99988022 | I10: =+$N10/$N$9 -> 0.93900019 | J10: =+$O10/$O$9 -> 0.99988015 | K10: =+ABS(LN($C10/$H10)) -> 3.2374261e-05 | L10: =+$L9-$P10 -> 30293127 | M10: =+$M9-$Q10-$R10 -> 44200979 | N10: =+$N9-$Q10 -> 13907867 | O10: =+$O9-$R10 -> 30293112 | P10: 3629 | Q10: 903490 | R10: 3631
A11: =+$A10+$A$1 -> 0.02 | B11: =+$M11/$M$9 -> 0.9665191 | C11: =2*(($A11/$C$1*$D11)^$C$2)^$C$3*BESSELK(2*(($A11/$C$1)*$D11)^$C$2,$C$3)/FACT($C$3-1) -> 0.99939304 | D11: =+(1-$D$2*$A11/$D$1*(1-$D$3*$A11/$D$1))^$D$4 -> 0.99896184 | G11: =+SQRT(1-$G$2*$A11/$G$1*(1-$G$3*$A11/$G$1)) -> 0.9999975 | H11: =+$L11/$L$9 -> 0.99954946 | I11: =+$N11/$N$9 -> 0.89895592 | J11: =+$O11/$O$9 -> 0.99954913 | K11: =+ABS(LN($C11/$H11)) -> 0.00015650264 | L11: =+$L10-$P11 -> 30283106 | M11: =+$M10-$Q11-$R11 -> 43597840 | N11: =+$N10-$Q11 -> 13314757 | O11: =+$O10-$R11 -> 30283083 | P11: 10021 | Q11: 593110 | R11: 10029
A12: =+$A11+$A$1 -> 0.03 | B12: =+$M12/$M$9 -> 0.95475048 | C12: =2*(($A12/$C$1*$D12)^$C$2)^$C$3*BESSELK(2*(($A12/$C$1)*$D12)^$C$2,$C$3)/FACT($C$3-1) -> 0.99863902 | D12: =+(1-$D$2*$A12/$D$1*(1-$D$3*$A12/$D$1))^$D$4 -> 0.99844298 | G12: =+SQRT(1-$G$2*$A12/$G$1*(1-$G$3*$A12/$G$1)) -> 0.99999625 | H12: =+$L12/$L$9 -> 0.99898719 | I12: =+$N12/$N$9 -> 0.86426706 | J12: =+$O12/$O$9 -> 0.99898567 | K12: =+ABS(LN($C12/$H12)) -> 0.00034857995 | L12: =+$L11-$P12 -> 30266071 | M12: =+$M11-$Q12-$R12 -> 43066980 | N12: =+$N11-$Q12 -> 12800968 | O12: =+$O11-$R12 -> 30266012 | P12: 17035 | Q12: 513789 | R12: 17071
A13: =+$A12+$A$1 -> 0.04 | B13: =+$M13/$M$9 -> 0.94444933 | C13: =2*(($A13/$C$1*$D13)^$C$2)^$C$3*BESSELK(2*(($A13/$C$1)*$D13)^$C$2,$C$3)/FACT($C$3-1) -> 0.99759025 | D13: =+(1-$D$2*$A13/$D$1*(1-$D$3*$A13/$D$1))^$D$4 -> 0.99792428 | G13: =+SQRT(1-$G$2*$A13/$G$1*(1-$G$3*$A13/$G$1)) -> 0.999995 | H13: =+$L13/$L$9 -> 0.99826678 | I13: =+$N13/$N$9 -> 0.83437446 | J13: =+$O13/$O$9 -> 0.99826232 | K13: =+ABS(LN($C13/$H13)) -> 0.00067793024 | L13: =+$L12-$P13 -> 30244245 | M13: =+$M12-$Q13-$R13 -> 42602315 | N13: =+$N12-$Q13 -> 12358218 | O13: =+$O12-$R13 -> 30244097 | P13: 21826 | Q13: 442750 | R13: 21915
A14: =+$A13+$A$1 -> 0.05 | B14: =+$M14/$M$9 -> 0.93580656 | C14: =2*(($A14/$C$1*$D14)^$C$2)^$C$3*BESSELK(2*(($A14/$C$1)*$D14)^$C$2,$C$3)/FACT($C$3-1) -> 0.99625195 | D14: =+(1-$D$2*$A14/$D$1*(1-$D$3*$A14/$D$1))^$D$4 -> 0.99740572 | G14: =+SQRT(1-$G$2*$A14/$G$1*(1-$G$3*$A14/$G$1)) -> 0.99999375 | H14: =+$L14/$L$9 -> 0.99737259 | I14: =+$N14/$N$9 -> 0.80989095 | J14: =+$O14/$O$9 -> 0.99736371 | K14: =+ABS(LN($C14/$H14)) -> 0.0011242195 | L14: =+$L13-$P14 -> 30217154 | M14: =+$M13-$Q14-$R14 -> 42212456 | N14: =+$N13-$Q14 -> 11995584 | O14: =+$O13-$R14 -> 30216872 | P14: 27091 | Q14: 362634 | R14: 27225
A15: =+$A14+$A$1 -> 0.06 | B15: =+$M15/$M$9 -> 0.92770383 | C15: =2*(($A15/$C$1*$D15)^$C$2)^$C$3*BESSELK(2*(($A15/$C$1)*$D15)^$C$2,$C$3)/FACT($C$3-1) -> 0.99462994 | D15: =+(1-$D$2*$A15/$D$1*(1-$D$3*$A15/$D$1))^$D$4 -> 0.99688732 | G15: =+SQRT(1-$G$2*$A15/$G$1*(1-$G$3*$A15/$G$1)) -> 0.9999925 | H15: =+$L15/$L$9 -> 0.99631713 | I15: =+$N15/$N$9 -> 0.78738714 | J15: =+$O15/$O$9 -> 0.99630132 | K15: =+ABS(LN($C15/$H15)) -> 0.0016948611 | L15: =+$L14-$P15 -> 30185177 | M15: =+$M14-$Q15-$R15 -> 41846957 | N15: =+$N14-$Q15 -> 11662272 | O15: =+$O14-$R15 -> 30184685 | P15: 31977 | Q15: 333312 | R15: 32187
A16: =+$A15+$A$1 -> 0.07 | B16: =+$M16/$M$9 -> 0.92021225 | C16: =2*(($A16/$C$1*$D16)^$C$2)^$C$3*BESSELK(2*(($A16/$C$1)*$D16)^$C$2,$C$3)/FACT($C$3-1) -> 0.99273051 | D16: =+(1-$D$2*$A16/$D$1*(1-$D$3*$A16/$D$1))^$D$4 -> 0.99636907 | G16: =+SQRT(1-$G$2*$A16/$G$1*(1-$G$3*$A16/$G$1)) -> 0.99999125 | H16: =+$L16/$L$9 -> 0.99510492 | I16: =+$N16/$N$9 -> 0.76706679 | J16: =+$O16/$O$9 -> 0.99508142 | K16: =+ABS(LN($C16/$H16)) -> 0.0023889458 | L16: =+$L15-$P16 -> 30148451 | M16: =+$M15-$Q16-$R16 -> 41509026 | N16: =+$N15-$Q16 -> 11361300 | O16: =+$O15-$R16 -> 30147726 | P16: 36726 | Q16: 300972 | R16: 36959
A17: =+$A16+$A$1 -> 0.08 | B17: =+$M17/$M$9 -> 0.91336798 | C17: =2*(($A17/$C$1*$D17)^$C$2)^$C$3*BESSELK(2*(($A17/$C$1)*$D17)^$C$2,$C$3)/FACT($C$3-1) -> 0.99056033 | D17: =+(1-$D$2*$A17/$D$1*(1-$D$3*$A17/$D$1))^$D$4 -> 0.99585097 | G17: =+SQRT(1-$G$2*$A17/$G$1*(1-$G$3*$A17/$G$1)) -> 0.99999 | H17: =+$L17/$L$9 -> 0.99373507 | I17: =+$N17/$N$9 -> 0.74904845 | J17: =+$O17/$O$9 -> 0.99369988 | K17: =+ABS(LN($C17/$H17)) -> 0.0031998754 | L17: =+$L16-$P17 -> 30106949 | M17: =+$M16-$Q17-$R17 -> 41200294 | N17: =+$N16-$Q17 -> 11094424 | O17: =+$O16-$R17 -> 30105870 | P17: 41502 | Q17: 266876 | R17: 41856
A18: =+$A17+$A$1 -> 0.09 | B18: =+$M18/$M$9 -> 0.90665337 | C18: =2*(($A18/$C$1*$D18)^$C$2)^$C$3*BESSELK(2*(($A18/$C$1)*$D18)^$C$2,$C$3)/FACT($C$3-1) -> 0.98812638 | D18: =+(1-$D$2*$A18/$D$1*(1-$D$3*$A18/$D$1))^$D$4 -> 0.99533302 | G18: =+SQRT(1-$G$2*$A18/$G$1*(1-$G$3*$A18/$G$1)) -> 0.99998875 | H18: =+$L18/$L$9 -> 0.99219553 | I18: =+$N18/$N$9 -> 0.73178697 | J18: =+$O18/$O$9 -> 0.9921414 | K18: =+ABS(LN($C18/$H18)) -> 0.0041095989 | L18: =+$L17-$P18 -> 30060306 | M18: =+$M17-$Q18-$R18 -> 40897411 | N18: =+$N17-$Q18 -> 10838758 | O18: =+$O17-$R18 -> 30058653 | P18: 46643 | Q18: 255666 | R18: 47217
A19: =+$A18+$A$1 -> 0.1 | B19: =+$M19/$M$9 -> 0.90036616 | C19: =2*(($A19/$C$1*$D19)^$C$2)^$C$3*BESSELK(2*(($A19/$C$1)*$D19)^$C$2,$C$3)/FACT($C$3-1) -> 0.98543587 | D19: =+(1-$D$2*$A19/$D$1*(1-$D$3*$A19/$D$1))^$D$4 -> 0.99481522 | G19: =+SQRT(1-$G$2*$A19/$G$1*(1-$G$3*$A19/$G$1)) -> 0.9999875 | H19: =+$L19/$L$9 -> 0.99050714 | I19: =+$N19/$N$9 -> 0.71613803 | J19: =+$O19/$O$9 -> 0.99043092 | K19: =+ABS(LN($C19/$H19)) -> 0.0051330143 | L19: =+$L18-$P19 -> 30009153 | M19: =+$M18-$Q19-$R19 -> 40613807 | N19: =+$N18-$Q19 -> 10606976 | O19: =+$O18-$R19 -> 30006831 | P19: 51153 | Q19: 231782 | R19: 51822
A20: =+$A19+$A$1 -> 0.11 | B20: =+$M20/$M$9 -> 0.89406377 | C20: =2*(($A20/$C$1*$D20)^$C$2)^$C$3*BESSELK(2*(($A20/$C$1)*$D20)^$C$2,$C$3)/FACT($C$3-1) -> 0.98249623 | D20: =+(1-$D$2*$A20/$D$1*(1-$D$3*$A20/$D$1))^$D$4 -> 0.99429758 | G20: =+SQRT(1-$G$2*$A20/$G$1*(1-$G$3*$A20/$G$1)) -> 0.99998625 | H20: =+$L20/$L$9 -> 0.98865651 | I20: =+$N20/$N$9 -> 0.7008029 | J20: =+$O20/$O$9 -> 0.98854441 | K20: =+ABS(LN($C20/$H20)) -> 0.0062504565 | L20: =+$L19-$P20 -> 29953085 | M20: =+$M19-$Q20-$R20 -> 40329518 | N20: =+$N19-$Q20 -> 10379842 | O20: =+$O19-$R20 -> 29949676 | P20: 56068 | Q20: 227134 | R20: 57155
A21: =+$A20+$A$1 -> 0.12 | B21: =+$M21/$M$9 -> 0.88791248 | C21: =2*(($A21/$C$1*$D21)^$C$2)^$C$3*BESSELK(2*(($A21/$C$1)*$D21)^$C$2,$C$3)/FACT($C$3-1) -> 0.97931497 | D21: =+(1-$D$2*$A21/$D$1*(1-$D$3*$A21/$D$1))^$D$4 -> 0.99378008 | G21: =+SQRT(1-$G$2*$A21/$G$1*(1-$G$3*$A21/$G$1)) -> 0.999985 | H21: =+$L21/$L$9 -> 0.98669039 | I21: =+$N21/$N$9 -> 0.68620228 | J21: =+$O21/$O$9 -> 0.9865238 | K21: =+ABS(LN($C21/$H21)) -> 0.0075029842 | L21: =+$L20-$P21 -> 29893518 | M21: =+$M20-$Q21-$R21 -> 40052045 | N21: =+$N20-$Q21 -> 10163587 | O21: =+$O20-$R21 -> 29888458 | P21: 59567 | Q21: 216255 | R21: 61218
A22: =+$A21+$A$1 -> 0.13 | B22: =+$M22/$M$9 -> 0.8818197 | C22: =2*(($A22/$C$1*$D22)^$C$2)^$C$3*BESSELK(2*(($A22/$C$1)*$D22)^$C$2,$C$3)/FACT($C$3-1) -> 0.97589975 | D22: =+(1-$D$2*$A22/$D$1*(1-$D$3*$A22/$D$1))^$D$4 -> 0.99326274 | G22: =+SQRT(1-$G$2*$A22/$G$1*(1-$G$3*$A22/$G$1)) -> 0.99998375 | H22: =+$L22/$L$9 -> 0.98453217 | I22: =+$N22/$N$9 -> 0.67223516 | J22: =+$O22/$O$9 -> 0.98428059 | K22: =+ABS(LN($C22/$H22)) -> 0.0088067102 | L22: =+$L21-$P22 -> 29828131 | M22: =+$M21-$Q22-$R22 -> 39777211 | N22: =+$N21-$Q22 -> 9956715 | O22: =+$O21-$R22 -> 29820496 | P22: 65387 | Q22: 206872 | R22: 67962
... A37: =+$A36+$A$1 -> 0.28 | B37: =+$M37/$M$9 -> 0.78575212 | C37: =2*(($A37/$C$1*$D37)^$C$2)^$C$3*BESSELK(2*(($A37/$C$1)*$D37)^$C$2,$C$3)/FACT($C$3-1) -> 0.90178911 | D37: =+(1-$D$2*$A37/$D$1*(1-$D$3*$A37/$D$1))^$D$4 -> 0.98552112 | G37: =+SQRT(1-$G$2*$A37/$G$1*(1-$G$3*$A37/$G$1)) -> 0.999965 | H37: =+$L37/$L$9 -> 0.93422646 | I37: =+$N37/$N$9 -> 0.49799043 | J37: =+$O37/$O$9 -> 0.92643196 | K37: =+ABS(LN($C37/$H37)) -> 0.035338179 | L37: =+$L36-$P37 -> 28304031 | M37: =+$M36-$Q37-$R37 -> 35443785 | N37: =+$N36-$Q37 -> 7375914 | O37: =+$O36-$R37 -> 28067871 | P37: 233735 | Q37: 248147 | R37: 281164
A38: =+$A37+$A$1 -> 0.29 | B38: =+$M38/$M$9 -> 0.78575212 | C38: =2*(($A38/$C$1*$D38)^$C$2)^$C$3*BESSELK(2*(($A38/$C$1)*$D38)^$C$2,$C$3)/FACT($C$3-1) -> 0.89565577 | D38: =+(1-$D$2*$A38/$D$1*(1-$D$3*$A38/$D$1))^$D$4 -> 0.98500625 | G38: =+SQRT(1-$G$2*$A38/$G$1*(1-$G$3*$A38/$G$1)) -> 0.99996375 | H38: =+$L38/$L$9 -> 0.93422646 | I38: =+$N38/$N$9 -> 0.49799043 | J38: =+$O38/$O$9 -> 0.92643196 | K38: =+ABS(LN($C38/$H38)) -> 0.04216271 | L38: =+$L37-$P38 -> 28304031 | M38: =+$M37-$Q38-$R38 -> 35443785 | N38: =+$N37-$Q38 -> 7375914 | O38: =+$O37-$R38 -> 28067871
A39: =+$A38+$A$1 -> 0.3 | B39: =+$M39/$M$9 -> 0.77983608 | C39: =2*(($A39/$C$1*$D39)^$C$2)^$C$3*BESSELK(2*(($A39/$C$1)*$D39)^$C$2,$C$3)/FACT($C$3-1) -> 0.88941224 | D39: =+(1-$D$2*$A39/$D$1*(1-$D$3*$A39/$D$1))^$D$4 -> 0.98449154 | G39: =+SQRT(1-$G$2*$A39/$G$1*(1-$G$3*$A39/$G$1)) -> 0.9999625 | H39: =+$L39/$L$9 -> 0.93023695 | I39: =+$N39/$N$9 -> 0.48985917 | J39: =+$O39/$O$9 -> 0.9215989 | K39: =+ABS(LN($C39/$H39)) -> 0.044878506 | L39: =+$L38-$P39 -> 28183162 | M39: =+$M38-$Q39-$R39 -> 35176924 | N39: =+$N38-$Q39 -> 7255479 | O39: =+$O38-$R39 -> 27921445 | P39: 120869 | Q39: 120435 | R39: 146426
A40: =+$A39+$A$1 -> 0.31 | B40: =+$M40/$M$9 -> 0.77385625 | C40: =2*(($A40/$C$1*$D40)^$C$2)^$C$3*BESSELK(2*(($A40/$C$1)*$D40)^$C$2,$C$3)/FACT($C$3-1) -> 0.88306477 | D40: =+(1-$D$2*$A40/$D$1*(1-$D$3*$A40/$D$1))^$D$4 -> 0.98397699 | G40: =+SQRT(1-$G$2*$A40/$G$1*(1-$G$3*$A40/$G$1)) -> 0.99996125 | H40: =+$L40/$L$9 -> 0.92615625 | I40: =+$N40/$N$9 -> 0.48178239 | J40: =+$O40/$O$9 -> 0.91664421 | K40: =+ABS(LN($C40/$H40)) -> 0.047644415 | L40: =+$L39-$P40 -> 28059530 | M40: =+$M39-$Q40-$R40 -> 34907185 | N40: =+$N39-$Q40 -> 7135851 | O40: =+$O39-$R40 -> 27771334 | P40: 123632 | Q40: 119628 | R40: 150111
A41: =+$A40+$A$1 -> 0.32 | B41: =+$M41/$M$9 -> 0.76779536 | C41: =2*(($A41/$C$1*$D41)^$C$2)^$C$3*BESSELK(2*(($A41/$C$1)*$D41)^$C$2,$C$3)/FACT($C$3-1) -> 0.87661948 | D41: =+(1-$D$2*$A41/$D$1*(1-$D$3*$A41/$D$1))^$D$4 -> 0.98346259 | G41: =+SQRT(1-$G$2*$A41/$G$1*(1-$G$3*$A41/$G$1)) -> 0.99996 | H41: =+$L41/$L$9 -> 0.92198396 | I41: =+$N41/$N$9 -> 0.47373391 | J41: =+$O41/$O$9 -> 0.91155501 | K41: =+ABS(LN($C41/$H41)) -> 0.050454814 | L41: =+$L40-$P41 -> 27933123 | M41: =+$M40-$Q41-$R41 -> 34633790 | N41: =+$N40-$Q41 -> 7016642 | O41: =+$O40-$R41 -> 27617148 | P41: 126407 | Q41: 119209 | R41: 154186
A42: =+$A41+$A$1 -> 0.33 | B42: =+$M42/$M$9 -> 0.76168657 | C42: =2*(($A42/$C$1*$D42)^$C$2)^$C$3*BESSELK(2*(($A42/$C$1)*$D42)^$C$2,$C$3)/FACT($C$3-1) -> 0.87008235 | D42: =+(1-$D$2*$A42/$D$1*(1-$D$3*$A42/$D$1))^$D$4 -> 0.98294836 | G42: =+SQRT(1-$G$2*$A42/$G$1*(1-$G$3*$A42/$G$1)) -> 0.99995875 | H42: =+$L42/$L$9 -> 0.91765435 | I42: =+$N42/$N$9 -> 0.46587008 | J42: =+$O42/$O$9 -> 0.90630422 | K42: =+ABS(LN($C42/$H42)) -> 0.053232932 | L42: =+$L41-$P42 -> 27801950 | M42: =+$M41-$Q42-$R42 -> 34358234 | N42: =+$N41-$Q42 -> 6900168 | O42: =+$O41-$R42 -> 27458066 | P42: 131173 | Q42: 116474 | R42: 159082
A43: =+$A42+$A$1 -> 0.34 | B43: =+$M43/$M$9 -> 0.75551214 | C43: =2*(($A43/$C$1*$D43)^$C$2)^$C$3*BESSELK(2*(($A43/$C$1)*$D43)^$C$2,$C$3)/FACT($C$3-1) -> 0.86345921 | D43: =+(1-$D$2*$A43/$D$1*(1-$D$3*$A43/$D$1))^$D$4 -> 0.98243428 | G43: =+SQRT(1-$G$2*$A43/$G$1*(1-$G$3*$A43/$G$1)) -> 0.9999575 | H43: =+$L43/$L$9 -> 0.91325583 | I43: =+$N43/$N$9 -> 0.45804088 | J43: =+$O43/$O$9 -> 0.90093876 | K43: =+ABS(LN($C43/$H43)) -> 0.05606939 | L43: =+$L42-$P43 -> 27668689 | M43: =+$M42-$Q43-$R43 -> 34079717 | N43: =+$N42-$Q43 -> 6784207 | O43: =+$O42-$R43 -> 27295510 | P43: 133261 | Q43: 115961 | R43: 162556
A44: =+$A43+$A$1 -> 0.35 | B44: =+$M44/$M$9 -> 0.74929361 | C44: =2*(($A44/$C$1*$D44)^$C$2)^$C$3*BESSELK(2*(($A44/$C$1)*$D44)^$C$2,$C$3)/FACT($C$3-1) -> 0.85675573 | D44: =+(1-$D$2*$A44/$D$1*(1-$D$3*$A44/$D$1))^$D$4 -> 0.98192036 | G44: =+SQRT(1-$G$2*$A44/$G$1*(1-$G$3*$A44/$G$1)) -> 0.99995625 | H44: =+$L44/$L$9 -> 0.90879406 | I44: =+$N44/$N$9 -> 0.45026462 | J44: =+$O44/$O$9 -> 0.89548177 | K44: =+ABS(LN($C44/$H44)) -> 0.05896567 | L44: =+$L43-$P44 -> 27533512 | M44: =+$M43-$Q44-$R44 -> 33799211 | N44: =+$N43-$Q44 -> 6669030 | O44: =+$O43-$R44 -> 27130181 | P44: 135177 | Q44: 115177 | R44: 165329
A45: =+$A44+$A$1 -> 0.36 | B45: =+$M45/$M$9 -> 0.74304763 | C45: =2*(($A45/$C$1*$D45)^$C$2)^$C$3*BESSELK(2*(($A45/$C$1)*$D45)^$C$2,$C$3)/FACT($C$3-1) -> 0.84997743 | D45: =+(1-$D$2*$A45/$D$1*(1-$D$3*$A45/$D$1))^$D$4 -> 0.98140659 | G45: =+SQRT(1-$G$2*$A45/$G$1*(1-$G$3*$A45/$G$1)) -> 0.999955 | H45: =+$L45/$L$9 -> 0.90424107 | I45: =+$N45/$N$9 -> 0.44269907 | J45: =+$O45/$O$9 -> 0.8898809 | K45: =+ABS(LN($C45/$H45)) -> 0.061886192 | L45: =+$L44-$P45 -> 27395571 | M45: =+$M44-$Q45-$R45 -> 33517467 | N45: =+$N44-$Q45 -> 6556974 | O45: =+$O44-$R45 -> 26960493 | P45: 137941 | Q45: 112056 | R45: 169688
A46: =+$A45+$A$1 -> 0.37 | B46: =+$M46/$M$9 -> 0.7367078 | C46: =2*(($A46/$C$1*$D46)^$C$2)^$C$3*BESSELK(2*(($A46/$C$1)*$D46)^$C$2,$C$3)/FACT($C$3-1) -> 0.84312971 | D46: =+(1-$D$2*$A46/$D$1*(1-$D$3*$A46/$D$1))^$D$4 -> 0.98089299 | G46: =+SQRT(1-$G$2*$A46/$G$1*(1-$G$3*$A46/$G$1)) -> 0.99995375 | H46: =+$L46/$L$9 -> 0.8995399 | I46: =+$N46/$N$9 -> 0.43515533 | J46: =+$O46/$O$9 -> 0.88412962 | K46: =+ABS(LN($C46/$H46)) -> 0.064762602 | L46: =+$L45-$P46 -> 27253141 | M46: =+$M45-$Q46-$R46 -> 33231489 | N46: =+$N45-$Q46 -> 6445241 | O46: =+$O45-$R46 -> 26786248 | P46: 142430 | Q46: 111733 | R46: 174245
A47: =+$A46+$A$1 -> 0.38 | B47: =+$M47/$M$9 -> 0.73032338 | C47: =2*(($A47/$C$1*$D47)^$C$2)^$C$3*BESSELK(2*(($A47/$C$1)*$D47)^$C$2,$C$3)/FACT($C$3-1) -> 0.83621779 | D47: =+(1-$D$2*$A47/$D$1*(1-$D$3*$A47/$D$1))^$D$4 -> 0.98037954 | G47: =+SQRT(1-$G$2*$A47/$G$1*(1-$G$3*$A47/$G$1)) -> 0.9999525 | H47: =+$L47/$L$9 -> 0.8947322 | I47: =+$N47/$N$9 -> 0.42773961 | J47: =+$O47/$O$9 -> 0.87824939 | K47: =+ABS(LN($C47/$H47)) -> 0.067635359 | L47: =+$L46-$P47 -> 27107483 | M47: =+$M46-$Q47-$R47 -> 32943500 | N47: =+$N46-$Q47 -> 6335404 | O47: =+$O46-$R47 -> 26608096 | P47: 145658 | Q47: 109837 | R47: 178152
A48: =+$A47+$A$1 -> 0.39 | B48: =+$M48/$M$9 -> 0.72396193 | C48: =2*(($A48/$C$1*$D48)^$C$2)^$C$3*BESSELK(2*(($A48/$C$1)*$D48)^$C$2,$C$3)/FACT($C$3-1) -> 0.82924675 | D48: =+(1-$D$2*$A48/$D$1*(1-$D$3*$A48/$D$1))^$D$4 -> 0.97986625 | G48: =+SQRT(1-$G$2*$A48/$G$1*(1-$G$3*$A48/$G$1)) -> 0.99995125 | H48: =+$L48/$L$9 -> 0.88991719 | I48: =+$N48/$N$9 -> 0.42048004 | J48: =+$O48/$O$9 -> 0.872327 | K48: =+ABS(LN($C48/$H48)) -> 0.070610654 | L48: =+$L47-$P48 -> 26961604 | M48: =+$M47-$Q48-$R48 -> 32656547 | N48: =+$N47-$Q48 -> 6227880 | O48: =+$O47-$R48 -> 26428667 | P48: 145879 | Q48: 107524 | R48: 179429
A49: =+$A48+$A$1 -> 0.4 | B49: =+$M49/$M$9 -> 0.71756924 | C49: =2*(($A49/$C$1*$D49)^$C$2)^$C$3*BESSELK(2*(($A49/$C$1)*$D49)^$C$2,$C$3)/FACT($C$3-1) -> 0.82222154 | D49: =+(1-$D$2*$A49/$D$1*(1-$D$3*$A49/$D$1))^$D$4 -> 0.97935313 | G49: =+SQRT(1-$G$2*$A49/$G$1*(1-$G$3*$A49/$G$1)) -> 0.99995 | H49: =+$L49/$L$9 -> 0.88502588 | I49: =+$N49/$N$9 -> 0.41337097 | J49: =+$O49/$O$9 -> 0.86628454 | K49: =+ABS(LN($C49/$H49)) -> 0.073607009 | L49: =+$L48-$P49 -> 26813413 | M49: =+$M48-$Q49-$R49 -> 32368185 | N49: =+$N48-$Q49 -> 6122585 | O49: =+$O48-$R49 -> 26245600 | P49: 148191 | Q49: 105295 | R49: 183067
A50: =+$A49+$A$1 -> 0.41 | B50: =+$M50/$M$9 -> 0.71109579 | C50: =2*(($A50/$C$1*$D50)^$C$2)^$C$3*BESSELK(2*(($A50/$C$1)*$D50)^$C$2,$C$3)/FACT($C$3-1) -> 0.81514695 | D50: =+(1-$D$2*$A50/$D$1*(1-$D$3*$A50/$D$1))^$D$4 -> 0.97884016 | G50: =+SQRT(1-$G$2*$A50/$G$1*(1-$G$3*$A50/$G$1)) -> 0.99994875 | H50: =+$L50/$L$9 -> 0.88001679 | I50: =+$N50/$N$9 -> 0.40634204 | J50: =+$O50/$O$9 -> 0.86008265 | K50: =+ABS(LN($C50/$H50)) -> 0.076572585 | L50: =+$L49-$P50 -> 26661654 | M50: =+$M49-$Q50-$R50 -> 32076180 | N50: =+$N49-$Q50 -> 6018477 | O50: =+$O49-$R50 -> 26057703 | P50: 151759 | Q50: 104108 | R50: 187897
... A52: =+$A51+$A$1 -> 0.43 | B52: =+$M52/$M$9 -> 0.69809318 | C52: =2*(($A52/$C$1*$D52)^$C$2)^$C$3*BESSELK(2*(($A52/$C$1)*$D52)^$C$2,$C$3)/FACT($C$3-1) -> 0.80086809 | D52: =+(1-$D$2*$A52/$D$1*(1-$D$3*$A52/$D$1))^$D$4 -> 0.9778147 | G52: =+SQRT(1-$G$2*$A52/$G$1*(1-$G$3*$A52/$G$1)) -> 0.99994625 | H52: =+$L52/$L$9 -> 0.86972411 | I52: =+$N52/$N$9 -> 0.39273417 | J52: =+$O52/$O$9 -> 0.84737594 | K52: =+ABS(LN($C52/$H52)) -> 0.082479793 | L52: =+$L51-$P52 -> 26349819 | M52: =+$M51-$Q52-$R52 -> 31489657 | N52: =+$N51-$Q52 -> 5816926 | O52: =+$O51-$R52 -> 25672731 | P52: 156550 | Q52: 97821 | R52: 193904
A53: =+$A52+$A$1 -> 0.44 | B53: =+$M53/$M$9 -> 0.69169732 | C53: =2*(($A53/$C$1*$D53)^$C$2)^$C$3*BESSELK(2*(($A53/$C$1)*$D53)^$C$2,$C$3)/FACT($C$3-1) -> 0.79367269 | D53: =+(1-$D$2*$A53/$D$1*(1-$D$3*$A53/$D$1))^$D$4 -> 0.97730221 | G53: =+SQRT(1-$G$2*$A53/$G$1*(1-$G$3*$A53/$G$1)) -> 0.999945 | H53: =+$L53/$L$9 -> 0.86452216 | I53: =+$N53/$N$9 -> 0.38648903 | J53: =+$O53/$O$9 -> 0.8409064 | K53: =+ABS(LN($C53/$H53)) -> 0.085505789 | L53: =+$L52-$P53 -> 26192217 | M53: =+$M52-$Q53-$R53 -> 31201152 | N53: =+$N52-$Q53 -> 5724427 | O53: =+$O52-$R53 -> 25476725 | P53: 157602 | Q53: 92499 | R53: 196006 | AE53: http://ocean.dmi.dk/wavestat/index.uk.php
A54: =+$A53+$A$1 -> 0.45 | B54: =+$M54/$M$9 -> 0.68522651 | C54: =2*(($A54/$C$1*$D54)^$C$2)^$C$3*BESSELK(2*(($A54/$C$1)*$D54)^$C$2,$C$3)/FACT($C$3-1) -> 0.78644568 | D54: =+(1-$D$2*$A54/$D$1*(1-$D$3*$A54/$D$1))^$D$4 -> 0.97678988 | G54: =+SQRT(1-$G$2*$A54/$G$1*(1-$G$3*$A54/$G$1)) -> 0.99994375 | H54: =+$L54/$L$9 -> 0.8592044 | I54: =+$N54/$N$9 -> 0.38030155 | J54: =+$O54/$O$9 -> 0.83429707 | K54: =+ABS(LN($C54/$H54)) -> 0.088483189 | L54: =+$L53-$P54 -> 26031106 | M54: =+$M53-$Q54-$R54 -> 30909266 | N54: =+$N53-$Q54 -> 5632782 | O54: =+$O53-$R54 -> 25276484 | P54: 161111 | Q54: 91645 | R54: 200241
A55: =+$A54+$A$1 -> 0.46 | B55: =+$M55/$M$9 -> 0.67862393 | C55: =2*(($A55/$C$1*$D55)^$C$2)^$C$3*BESSELK(2*(($A55/$C$1)*$D55)^$C$2,$C$3)/FACT($C$3-1) -> 0.77919114 | D55: =+(1-$D$2*$A55/$D$1*(1-$D$3*$A55/$D$1))^$D$4 -> 0.97627771 | G55: =+SQRT(1-$G$2*$A55/$G$1*(1-$G$3*$A55/$G$1)) -> 0.9999425 | H55: =+$L55/$L$9 -> 0.85375025 | I55: =+$N55/$N$9 -> 0.37396999 | J55: =+$O55/$O$9 -> 0.82756199 | K55: =+ABS(LN($C55/$H55)) -> 0.091382324 | L55: =+$L54-$P55 -> 25865863 | M55: =+$M54-$Q55-$R55 -> 30611436 | N55: =+$N54-$Q55 -> 5539003 | O55: =+$O54-$R55 -> 25072433 | P55: 165243 | Q55: 93779 | R55: 204051
A56: =+$A55+$A$1 -> 0.47 | B56: =+$M56/$M$9 -> 0.67191012 | C56: =2*(($A56/$C$1*$D56)^$C$2)^$C$3*BESSELK(2*(($A56/$C$1)*$D56)^$C$2,$C$3)/FACT($C$3-1) -> 0.77191303 | D56: =+(1-$D$2*$A56/$D$1*(1-$D$3*$A56/$D$1))^$D$4 -> 0.97576571 | G56: =+SQRT(1-$G$2*$A56/$G$1*(1-$G$3*$A56/$G$1)) -> 0.99994125 | H56: =+$L56/$L$9 -> 0.84818866 | I56: =+$N56/$N$9 -> 0.36756065 | J56: =+$O56/$O$9 -> 0.82069934 | K56: =+ABS(LN($C56/$H56)) -> 0.094231203 | L56: =+$L55-$P56 -> 25697365 | M56: =+$M55-$Q56-$R56 -> 30308589 | N56: =+$N55-$Q56 -> 5444072 | O56: =+$O55-$R56 -> 24864517 | P56: 168498 | Q56: 94931 | R56: 207916
...

Sheet lake_superior
A1: 0.01 | B1: 0.9 | C1: 0.85 | D1: 16 | E1: 123.03273 | H1: =+SUM(H10:H1118) -> 338.17868 | J1: best fit | K1: 0.9 | L1: 22.823147
B2: 1 | C2: 1 | D2: 2.7 | H2: goal | K2: 1 | L2: 3.3665352
B3: 1 | C3: 1 | D3: 1.05 | K3: 1 | L3: 1.4434418
D4: 0.5
D6: 2.5 | M6: =+SUM($M10:$M5000) -> 8882880
I7: Cumulative
I8: RMS | M8: RMS
C9: Model | D9: Nonlinear | E9: RMS | I9: =+M9 -> 8882880 | M9: =+SUM($M10:$M5000) -> 8882880
A10: 0.01 | C10: =2*($A10*$D10/$C$1)^$C$3*BESSELK(2*($A10*$D10/$C$1)^$C$3,$C$2)/FACT($C$2-1) -> 0.99879328 | D10: =+(1-$D$2*$A10/$D$1*(1-$D$3*$A10/$D$1))^$D$4 -> 0.99915645 | E10: =+$I10/$I$9 -> 1 | H10: =+ABS(LN($C10/$E10)) -> 0.0012074468 | I10: =+$I9-$M10 -> 8882880
A11: =+$A10+$A$1 -> 0.02 | C11: =2*($A11*$D11/$C$1)^$C$3*BESSELK(2*($A11*$D11/$C$1)^$C$3,$C$2)/FACT($C$2-1) -> 0.99594429 | D11: =+(1-$D$2*$A11/$D$1*(1-$D$3*$A11/$D$1))^$D$4 -> 0.99831329 | E11: =+$I11/$I$9 -> 1 | H11: =+ABS(LN($C11/$E11)) -> 0.0040639528 | I11: =+$I10-$M11 -> 8882880
A12: =+$A11+$A$1 -> 0.03 | C12: =2*($A12*$D12/$C$1)^$C$3*BESSELK(2*($A12*$D12/$C$1)^$C$3,$C$2)/FACT($C$2-1) -> 0.99188987 | D12: =+(1-$D$2*$A12/$D$1*(1-$D$3*$A12/$D$1))^$D$4 -> 0.99747053 | E12: =+$I12/$I$9 -> 1 | H12: =+ABS(LN($C12/$E12)) -> 0.0081431961 | I12: =+$I11-$M12 -> 8882880
A13: =+$A12+$A$1 -> 0.04 | C13: =2*($A13*$D13/$C$1)^$C$3*BESSELK(2*($A13*$D13/$C$1)^$C$3,$C$2)/FACT($C$2-1) -> 0.98686109 | D13: =+(1-$D$2*$A13/$D$1*(1-$D$3*$A13/$D$1))^$D$4 -> 0.99662817 | E13: =+$I13/$I$9 -> 1 | H13: =+ABS(LN($C13/$E13)) -> 0.013225985 | I13: =+$I12-$M13 -> 8882880
A14: =+$A13+$A$1 -> 0.05 | C14: =2*($A14*$D14/$C$1)^$C$3*BESSELK(2*($A14*$D14/$C$1)^$C$3,$C$2)/FACT($C$2-1) -> 0.98101742 | D14: =+(1-$D$2*$A14/$D$1*(1-$D$3*$A14/$D$1))^$D$4 -> 0.99578621 | E14: =+$I14/$I$9 -> 1 | H14: =+ABS(LN($C14/$E14)) -> 0.01916506 | I14: =+$I13-$M14 -> 8882880
A15: =+$A14+$A$1 -> 0.06 | C15: =2*($A15*$D15/$C$1)^$C$3*BESSELK(2*($A15*$D15/$C$1)^$C$3,$C$2)/FACT($C$2-1) -> 0.9744799 | D15: =+(1-$D$2*$A15/$D$1*(1-$D$3*$A15/$D$1))^$D$4 -> 0.99494466 | E15: =+$I15/$I$9 -> 1 | H15: =+ABS(LN($C15/$E15)) -> 0.025851389 | I15: =+$I14-$M15 -> 8882880
A16: =+$A15+$A$1 -> 0.07 | C16: =2*($A16*$D16/$C$1)^$C$3*BESSELK(2*($A16*$D16/$C$1)^$C$3,$C$2)/FACT($C$2-1) -> 0.96734532 | D16: =+(1-$D$2*$A16/$D$1*(1-$D$3*$A16/$D$1))^$D$4 -> 0.9941035 | E16: =+$I16/$I$9 -> 1 | H16: =+ABS(LN($C16/$E16)) -> 0.033199747 | I16: =+$I15-$M16 -> 8882880
A17: =+$A16+$A$1 -> 0.08 | C17: =2*($A17*$D17/$C$1)^$C$3*BESSELK(2*($A17*$D17/$C$1)^$C$3,$C$2)/FACT($C$2-1) -> 0.95969367 | D17: =+(1-$D$2*$A17/$D$1*(1-$D$3*$A17/$D$1))^$D$4 -> 0.99326274 | E17: =+$I17/$I$9 -> 1 | H17: =+ABS(LN($C17/$E17)) -> 0.041141135 | I17: =+$I16-$M17 -> 8882880
A18: =+$A17+$A$1 -> 0.09 | C18: =2*($A18*$D18/$C$1)^$C$3*BESSELK(2*($A18*$D18/$C$1)^$C$3,$C$2)/FACT($C$2-1) -> 0.9515926 | D18: =+(1-$D$2*$A18/$D$1*(1-$D$3*$A18/$D$1))^$D$4 -> 0.99242239 | E18: =+$I18/$I$9 -> 1 | H18: =+ABS(LN($C18/$E18)) -> 0.049618274 | I18: =+$I17-$M18 -> 8882880
A19: =+$A18+$A$1 -> 0.1 | C19: =2*($A19*$D19/$C$1)^$C$3*BESSELK(2*($A19*$D19/$C$1)^$C$3,$C$2)/FACT($C$2-1) -> 0.94310022 | D19: =+(1-$D$2*$A19/$D$1*(1-$D$3*$A19/$D$1))^$D$4 -> 0.99158244 | E19: =+$I19/$I$9 -> 0.9781322 | H19: =+ABS(LN($C19/$E19)) -> 0.036472281 | I19: =+$I18-$M19 -> 8688631 | M19: 194249
A20: =+$A19+$A$1 -> 0.11 | C20: =2*($A20*$D20/$C$1)^$C$3*BESSELK(2*($A20*$D20/$C$1)^$C$3,$C$2)/FACT($C$2-1) -> 0.93426711 | D20: =+(1-$D$2*$A20/$D$1*(1-$D$3*$A20/$D$1))^$D$4 -> 0.9907429 | E20: =+$I20/$I$9 -> 0.9781322 | H20: =+ABS(LN($C20/$E20)) -> 0.045882454 | I20: =+$I19-$M20 -> 8688631
A21: =+$A20+$A$1 -> 0.12 | C21: =2*($A21*$D21/$C$1)^$C$3*BESSELK(2*($A21*$D21/$C$1)^$C$3,$C$2)/FACT($C$2-1) -> 0.92513771 | D21: =+(1-$D$2*$A21/$D$1*(1-$D$3*$A21/$D$1))^$D$4 -> 0.98990377 | E21: =+$I21/$I$9 -> 0.9781322 | H21: =+ABS(LN($C21/$E21)) -> 0.05570224 | I21: =+$I20-$M21 -> 8688631
A22: =+$A21+$A$1 -> 0.13 | C22: =2*($A22*$D22/$C$1)^$C$3*BESSELK(2*($A22*$D22/$C$1)^$C$3,$C$2)/FACT($C$2-1) -> 0.91575135 | D22: =+(1-$D$2*$A22/$D$1*(1-$D$3*$A22/$D$1))^$D$4 -> 0.98906504 | E22: =+$I22/$I$9 -> 0.9781322 | H22: =+ABS(LN($C22/$E22)) -> 0.065899964 | I22: =+$I21-$M22 -> 8688631
A23: =+$A22+$A$1 -> 0.14 | C23: =2*($A23*$D23/$C$1)^$C$3*BESSELK(2*($A23*$D23/$C$1)^$C$3,$C$2)/FACT($C$2-1) -> 0.90614309 | D23: =+(1-$D$2*$A23/$D$1*(1-$D$3*$A23/$D$1))^$D$4 -> 0.98822672 | E23: =+$I23/$I$9 -> 0.9781322 | H23: =+ABS(LN($C23/$E23)) -> 0.07644761 | I23: =+$I22-$M23 -> 8688631
A24: =+$A23+$A$1 -> 0.15 | C24: =2*($A24*$D24/$C$1)^$C$3*BESSELK(2*($A24*$D24/$C$1)^$C$3,$C$2)/FACT($C$2-1) -> 0.89634431 | D24: =+(1-$D$2*$A24/$D$1*(1-$D$3*$A24/$D$1))^$D$4 -> 0.98738881 | E24: =+$I24/$I$9 -> 0.9781322 | H24: =+ABS(LN($C24/$E24)) -> 0.087320227 | I24: =+$I23-$M24 -> 8688631
A25: =+$A24+$A$1 -> 0.16 | C25: =2*($A25*$D25/$C$1)^$C$3*BESSELK(2*($A25*$D25/$C$1)^$C$3,$C$2)/FACT($C$2-1) -> 0.88638322 | D25: =+(1-$D$2*$A25/$D$1*(1-$D$3*$A25/$D$1))^$D$4 -> 0.98655132 | E25: =+$I25/$I$9 -> 0.9781322 | H25: =+ABS(LN($C25/$E25)) -> 0.098495449 | I25: =+$I24-$M25 -> 8688631
A26: =+$A25+$A$1 -> 0.17 | C26: =2*($A26*$D26/$C$1)^$C$3*BESSELK(2*($A26*$D26/$C$1)^$C$3,$C$2)/FACT($C$2-1) -> 0.87628529 | D26: =+(1-$D$2*$A26/$D$1*(1-$D$3*$A26/$D$1))^$D$4 -> 0.98571423 | E26: =+$I26/$I$9 -> 0.9781322 | H26: =+ABS(LN($C26/$E26)) -> 0.10995313 | I26: =+$I25-$M26 -> 8688631
A27: =+$A26+$A$1 -> 0.18 | C27: =2*($A27*$D27/$C$1)^$C$3*BESSELK(2*($A27*$D27/$C$1)^$C$3,$C$2)/FACT($C$2-1) -> 0.86607355 | D27: =+(1-$D$2*$A27/$D$1*(1-$D$3*$A27/$D$1))^$D$4 -> 0.98487756 | E27: =+$I27/$I$9 -> 0.9781322 | H27: =+ABS(LN($C27/$E27)) -> 0.12167501 | I27: =+$I26-$M27 -> 8688631
A28: =+$A27+$A$1 -> 0.19 | C28: =2*($A28*$D28/$C$1)^$C$3*BESSELK(2*($A28*$D28/$C$1)^$C$3,$C$2)/FACT($C$2-1) -> 0.85576888 | D28: =+(1-$D$2*$A28/$D$1*(1-$D$3*$A28/$D$1))^$D$4 -> 0.9840413 | E28: =+$I28/$I$9 -> 0.9781322 | H28: =+ABS(LN($C28/$E28)) -> 0.1336445 | I28: =+$I27-$M28 -> 8688631
A29: =+$A28+$A$1 -> 0.2 | C29: =2*($A29*$D29/$C$1)^$C$3*BESSELK(2*($A29*$D29/$C$1)^$C$3,$C$2)/FACT($C$2-1) -> 0.84539027 | D29: =+(1-$D$2*$A29/$D$1*(1-$D$3*$A29/$D$1))^$D$4 -> 0.98320546 | E29: =+$I29/$I$9 -> 0.91083196 | H29: =+ABS(LN($C29/$E29)) -> 0.074560042 | I29: =+$I28-$M29 -> 8090811 | M29: 597820
A30: =+$A29+$A$1 -> 0.21 | C30: =2*($A30*$D30/$C$1)^$C$3*BESSELK(2*($A30*$D30/$C$1)^$C$3,$C$2)/FACT($C$2-1) -> 0.83495501 | D30: =+(1-$D$2*$A30/$D$1*(1-$D$3*$A30/$D$1))^$D$4 -> 0.98237003 | E30: =+$I30/$I$9 -> 0.91083196 | H30: =+ABS(LN($C30/$E30)) -> 0.086980581 | I30: =+$I29-$M30 -> 8090811
A31: =+$A30+$A$1 -> 0.22 | C31: =2*($A31*$D31/$C$1)^$C$3*BESSELK(2*($A31*$D31/$C$1)^$C$3,$C$2)/FACT($C$2-1) -> 0.82447884 | D31: =+(1-$D$2*$A31/$D$1*(1-$D$3*$A31/$D$1))^$D$4 -> 0.98153502 | E31: =+$I31/$I$9 -> 0.91083196 | H31: =+ABS(LN($C31/$E31)) -> 0.099606946 | I31: =+$I30-$M31 -> 8090811
A32: =+$A31+$A$1 -> 0.23 | C32: =2*($A32*$D32/$C$1)^$C$3*BESSELK(2*($A32*$D32/$C$1)^$C$3,$C$2)/FACT($C$2-1) -> 0.81397614 | D32: =+(1-$D$2*$A32/$D$1*(1-$D$3*$A32/$D$1))^$D$4 -> 0.98070043 | E32: =+$I32/$I$9 -> 0.91083196 | H32: =+ABS(LN($C32/$E32)) -> 0.11242738 | I32: =+$I31-$M32 -> 8090811
A33: =+$A32+$A$1 -> 0.24 | C33: =2*($A33*$D33/$C$1)^$C$3*BESSELK(2*($A33*$D33/$C$1)^$C$3,$C$2)/FACT($C$2-1) -> 0.80346002 | D33: =+(1-$D$2*$A33/$D$1*(1-$D$3*$A33/$D$1))^$D$4 -> 0.97986625 | E33: =+$I33/$I$9 -> 0.91083196 | H33: =+ABS(LN($C33/$E33)) -> 0.125431 | I33: =+$I32-$M33 -> 8090811
A34: =+$A33+$A$1 -> 0.25 | C34: =2*($A34*$D34/$C$1)^$C$3*BESSELK(2*($A34*$D34/$C$1)^$C$3,$C$2)/FACT($C$2-1) -> 0.79294247 | D34: =+(1-$D$2*$A34/$D$1*(1-$D$3*$A34/$D$1))^$D$4 -> 0.9790325 | E34: =+$I34/$I$9 -> 0.91083196 | H34: =+ABS(LN($C34/$E34)) -> 0.13860775 | I34: =+$I33-$M34 -> 8090811
A35: =+$A34+$A$1 -> 0.26 | C35: =2*($A35*$D35/$C$1)^$C$3*BESSELK(2*($A35*$D35/$C$1)^$C$3,$C$2)/FACT($C$2-1) -> 0.78243446 | D35: =+(1-$D$2*$A35/$D$1*(1-$D$3*$A35/$D$1))^$D$4 -> 0.97819917 | E35: =+$I35/$I$9 -> 0.91083196 | H35: =+ABS(LN($C35/$E35)) -> 0.15194826 | I35: =+$I34-$M35 -> 8090811
A36: =+$A35+$A$1 -> 0.27 | C36: =2*($A36*$D36/$C$1)^$C$3*BESSELK(2*($A36*$D36/$C$1)^$C$3,$C$2)/FACT($C$2-1) -> 0.77194599 | D36: =+(1-$D$2*$A36/$D$1*(1-$D$3*$A36/$D$1))^$D$4 -> 0.97736626 | E36: =+$I36/$I$9 -> 0.91083196 | H36: =+ABS(LN($C36/$E36)) -> 0.16544383 | I36: =+$I35-$M36 -> 8090811
A37: =+$A36+$A$1 -> 0.28 | C37: =2*($A37*$D37/$C$1)^$C$3*BESSELK(2*($A37*$D37/$C$1)^$C$3,$C$2)/FACT($C$2-1) -> 0.76148623 | D37: =+(1-$D$2*$A37/$D$1*(1-$D$3*$A37/$D$1))^$D$4 -> 0.97653378 | E37: =+$I37/$I$9 -> 0.91083196 | H37: =+ABS(LN($C37/$E37)) -> 0.17908634 | I37: =+$I36-$M37 -> 8090811
A38: =+$A37+$A$1 -> 0.29 | C38: =2*($A38*$D38/$C$1)^$C$3*BESSELK(2*($A38*$D38/$C$1)^$C$3,$C$2)/FACT($C$2-1) -> 0.75106353 | D38: =+(1-$D$2*$A38/$D$1*(1-$D$3*$A38/$D$1))^$D$4 -> 0.97570172 | E38: =+$I38/$I$9 -> 0.91083196 | H38: =+ABS(LN($C38/$E38)) -> 0.19286818 | I38: =+$I37-$M38 -> 8090811
A39: =+$A38+$A$1 -> 0.3 | C39: =2*($A39*$D39/$C$1)^$C$3*BESSELK(2*($A39*$D39/$C$1)^$C$3,$C$2)/FACT($C$2-1) -> 0.74068554 | D39: =+(1-$D$2*$A39/$D$1*(1-$D$3*$A39/$D$1))^$D$4 -> 0.97487008 | E39: =+$I39/$I$9 -> 0.81816911 | H39: =+ABS(LN($C39/$E39)) -> 0.099492886 | I39: =+$I38-$M39 -> 7267698 | M39: 823113
A40: =+$A39+$A$1 -> 0.31 | C40: =2*($A40*$D40/$C$1)^$C$3*BESSELK(2*($A40*$D40/$C$1)^$C$3,$C$2)/FACT($C$2-1) -> 0.73035923 | D40: =+(1-$D$2*$A40/$D$1*(1-$D$3*$A40/$D$1))^$D$4 -> 0.97403888 | E40: =+$I40/$I$9 -> 0.81816911 | H40: =+ABS(LN($C40/$E40)) -> 0.11353253 | I40: =+$I39-$M40 -> 7267698
A41: =+$A40+$A$1 -> 0.32 | C41: =2*($A41*$D41/$C$1)^$C$3*BESSELK(2*($A41*$D41/$C$1)^$C$3,$C$2)/FACT($C$2-1) -> 0.72009097 | D41: =+(1-$D$2*$A41/$D$1*(1-$D$3*$A41/$D$1))^$D$4 -> 0.9732081 | E41: =+$I41/$I$9 -> 0.81816911 | H41: =+ABS(LN($C41/$E41)) -> 0.12769149 | I41: =+$I40-$M41 -> 7267698
...

Sheet NA
A1: 0.01 | C1: 1.7 | D1: 40 | E1: 123.03273 | F1: 0.95
C2: 2 | D2: 2.5
D3: 1.75
D4: =+$D$2*$D$3 -> 4.375
D6: 40 | F6: 0.95 | M6: =+SUM($M10:$M5000) -> 0
I7: Cumulative
I8: RMS | M8: RMS
C9: Model | D9: Nonlinear | E9: North Atlantic Sea State model | F9: Tayfun | I9: =+M9 -> 0 | M9: =+SUM($M10:$M5000) -> 0
A10: 0.1 | C10: =2*($A10*$D10/$C$1)^$C$2*BESSELK(2*$A10*$D10/$C$1,$C$2)/FACT($C$2-1) -> 0.99661795 | D10: =+(1-$D$2*$A10/$D$1*(1-$D$3*$A10/$D$1)) -> 0.99377734 | E10: 0.993 | F10: =+ EXP(-($F$1*$A10+1-SQRT(2*$F$1*$A10+1))) -> 0.99587972 | I10: =+$I9-$M10 -> 0
A11: 0.5 | C11: =2*($A11*$D11/$C$1)^$C$2*BESSELK(2*$A11*$D11/$C$1,$C$2)/FACT($C$2-1) -> 0.92851739 | D11: =+(1-$D$2*$A11/$D$1*(1-$D$3*$A11/$D$1)) -> 0.96943359 | E11: =+$E10-0.068 -> 0.925 | F11: =+ EXP(-($F$1*$A11+1-SQRT(2*$F$1*$A11+1))) -> 0.9244318 | I11: =+$I10-$M11 -> 0
A12: 1.25 | C12: =2*($A12*$D12/$C$1)^$C$2*BESSELK(2*$A12*$D12/$C$1,$C$2)/FACT($C$2-1) -> 0.69991438 | D12: =+(1-$D$2*$A12/$D$1*(1-$D$3*$A12/$D$1)) -> 0.92614746 | E12: =+$E11-0.237 -> 0.688 | F12: =+ EXP(-($F$1*$A12+1-SQRT(2*$F$1*$A12+1))) -> 0.70441846 | I12: =+$I11-$M12 -> 0
A13: 2.5 | C13: =2*($A13*$D13/$C$1)^$C$2*BESSELK(2*$A13*$D13/$C$1,$C$2)/FACT($C$2-1) -> 0.37225343 | D13: =+(1-$D$2*$A13/$D$1*(1-$D$3*$A13/$D$1)) -> 0.86083984 | E13: =+$E12-0.278 -> 0.41 | F13: =+ EXP(-($F$1*$A13+1-SQRT(2*$F$1*$A13+1))) -> 0.37640701 | I13: =+$I12-$M13 -> 0
A14: 4 | C14: =2*($A14*$D14/$C$1)^$C$2*BESSELK(2*$A14*$D14/$C$1,$C$2)/FACT($C$2-1) -> 0.16800295 | D14: =+(1-$D$2*$A14/$D$1*(1-$D$3*$A14/$D$1)) -> 0.79375 | E14: =+$E13-0.2064 -> 0.2036 | F14: =+ EXP(-($F$1*$A14+1-SQRT(2*$F$1*$A14+1))) -> 0.15452114 | I14: =+$I13-$M14 -> 0
A15: 6 | C15: =2*($A15*$D15/$C$1)^$C$2*BESSELK(2*$A15*$D15/$C$1,$C$2)/FACT($C$2-1) -> 0.061171663 | D15: =+(1-$D$2*$A15/$D$1*(1-$D$3*$A15/$D$1)) -> 0.7234375 | E15: =+$E14-0.1315 -> 0.0721 | F15: =+ EXP(-($F$1*$A15+1-SQRT(2*$F$1*$A15+1))) -> 0.041642391 | I15: =+$I14-$M15 -> 0
A16: 9 | C16: =2*($A16*$D16/$C$1)^$C$2*BESSELK(2*$A16*$D16/$C$1,$C$2)/FACT($C$2-1) -> 0.013839594 | D16: =+(1-$D$2*$A16/$D$1*(1-$D$3*$A16/$D$1)) -> 0.65898437 | E16: =+$E15-0.0605 -> 0.0116 | F16: =+ EXP(-($F$1*$A16+1-SQRT(2*$F$1*$A16+1))) -> 0.0050136528 | I16: =+$I15-$M16 -> 0
A17: 14 | C17: =2*($A17*$D17/$C$1)^$C$2*BESSELK(2*$A17*$D17/$C$1,$C$2)/FACT($C$2-1) -> 0.00049668876 | D17: =+(1-$D$2*$A17/$D$1*(1-$D$3*$A17/$D$1)) -> 0.6609375 | E17: =+$E16-0.0111 -> 0.0005 | F17: =+ EXP(-($F$1*$A17+1-SQRT(2*$F$1*$A17+1))) -> 0.0001178109 | I17: =+$I16-$M17 -> 0
A18: 15 | C18: =2*($A18*$D18/$C$1)^$C$2*BESSELK(2*$A18*$D18/$C$1,$C$2)/FACT($C$2-1) -> 0.00019265988 | D18: =+(1-$D$2*$A18/$D$1*(1-$D$3*$A18/$D$1)) -> 0.67773438 | E18: =+$E17-0.0005 -> 2.6454533e-17 | F18: =+ EXP(-($F$1*$A18+1-SQRT(2*$F$1*$A18+1))) -> 5.4429202e-05 | I18: =+$I17-$M18 -> 0

Sheet Sheet1
A1: 1 | B1: 1.4
B2: 1
A3: -10 | B3: =+($B$2*ABS($A3))^$B$1 -> 25.118864
A4: =+$A3+$A$1 -> -9 | B4: =+($B$2*ABS($A4))^$B$1 -> 21.674022
A5: =+$A4+$A$1 -> -8 | B5: =+($B$2*ABS($A5))^$B$1 -> 18.379174
A6: =+$A5+$A$1 -> -7 | B6: =+($B$2*ABS($A6))^$B$1 -> 15.245345
A7: =+$A6+$A$1 -> -6 | B7: =+($B$2*ABS($A7))^$B$1 -> 12.286035
A8: =+$A7+$A$1 -> -5 | B8: =+($B$2*ABS($A8))^$B$1 -> 9.5182697
A9: =+$A8+$A$1 -> -4 | B9: =+($B$2*ABS($A9))^$B$1 -> 6.9644045
A10: =+$A9+$A$1 -> -3 | B10: =+($B$2*ABS($A10))^$B$1 -> 4.6555367
A11: =+$A10+$A$1 -> -2 | B11: =+($B$2*ABS($A11))^$B$1 -> 2.6390158
A12: =+$A11+$A$1 -> -1 | B12: =+($B$2*ABS($A12))^$B$1 -> 1
A13: =+$A12+$A$1 -> 0 | B13: =+($B$2*ABS($A13))^$B$1 -> 0
A14: =+$A13+$A$1 -> 1 | B14: =+($B$2*ABS($A14))^$B$1 -> 1
A15: =+$A14+$A$1 -> 2 | B15: =+($B$2*ABS($A15))^$B$1 -> 2.6390158
... A23: =+$A22+$A$1 -> 10 | B23: =+($B$2*ABS($A23))^$B$1 -> 25.118864
A24: =+$A23+$A$1 -> 11
A25: =+$A24+$A$1 -> 12
A26: =+$A25+$A$1 -> 13
A27: =+$A26+$A$1 -> 14
A28: =+$A27+$A$1 -> 15
A29: =+$A28+$A$1 -> 16
A30: =+$A29+$A$1 -> 17
A31: =+$A30+$A$1 -> 18
A32: =+$A31+$A$1 -> 19
A33: =+$A32+$A$1 -> 20
A34: =+$A33+$A$1 -> 21
A35: =+$A34+$A$1 -> 22
... A91: =+$A90+$A$1 -> 78

Sheet Parameters
C1: =+east_coast!D1 -> 26 | E1: =+lake_superior!D1 -> 16 | G1: =+lake_michigan!D1 -> 12.5 | H1: Average Depth
C2: =+east_coast!D2 -> 2.7 | E2: =+lake_superior!D2 -> 2.7 | G2: =+lake_michigan!D2 -> 2.7 | H2: First | I2: 2.49 | J2: from Forrestal
A3: 0.1 | C3: =+east_coast!D3 -> 1.05 | E3: =+lake_superior!D3 -> 1.05 | G3: =+lake_michigan!D3 -> 1.05 | H3: Second | I3: 1.755
C4: Atlantic Seaboard | E4: Lake Superior | G4: Lake Michigan
A5: 0 | B5: =+$A5/$C$1 -> 0 | C5: =+(1-2.5/40*$A5*(1-1.5/40*$A5)) -> 1 | D5: =+$A5/$E$1 -> 0 | E5: =+(1-2.5/27*$A5*(1-1.75/27*$A5)) -> 1 | F5: =+$A5/$G$1 -> 0 | G5: =+(1-2.4/19*$A5*(1-1.7/19*$A5)) -> 1
A6: =+$A5+$A$3 -> 0.1 | B6: =+$A6/$C$1 -> 0.0038461538 | C6: =+SQRT(1-C$2/C$1*$A6*(1-C$3/C$1*$A6)) -> 0.99481522 | D6: =+$A6/$E$1 -> 0.00625 | E6: =+SQRT(1-E$2/E$1*$A6*(1-E$3/E$1*$A6)) -> 0.99158244 | F6: =+$A6/$G$1 -> 0.008 | G6: =+SQRT(1-G$2/G$1*$A6*(1-G$3/G$1*$A6)) -> 0.98923275
A7: =+$A6+$A$3 -> 0.2 | B7: =+$A7/$C$1 -> 0.0076923077 | C7: =+SQRT(1-C$2/C$1*$A7*(1-C$3/C$1*$A7)) -> 0.98964565 | D7: =+$A7/$E$1 -> 0.0125 | E7: =+SQRT(1-E$2/E$1*$A7*(1-E$3/E$1*$A7)) -> 0.98320546 | F7: =+$A7/$G$1 -> 0.016 | G7: =+SQRT(1-G$2/G$1*$A7*(1-G$3/G$1*$A7)) -> 0.97853245
A8: =+$A7+$A$3 -> 0.3 | B8: =+$A8/$C$1 -> 0.011538462 | C8: =+SQRT(1-C$2/C$1*$A8*(1-C$3/C$1*$A8)) -> 0.98449154 | D8: =+$A8/$E$1 -> 0.01875 | E8: =+SQRT(1-E$2/E$1*$A8*(1-E$3/E$1*$A8)) -> 0.97487008 | F8: =+$A8/$G$1 -> 0.024 | G8: =+SQRT(1-G$2/G$1*$A8*(1-G$3/G$1*$A8)) -> 0.96790132
A9: =+$A8+$A$3 -> 0.4 | B9: =+$A9/$C$1 -> 0.015384615 | C9: =+SQRT(1-C$2/C$1*$A9*(1-C$3/C$1*$A9)) -> 0.97935313 | D9: =+$A9/$E$1 -> 0.025 | E9: =+SQRT(1-E$2/E$1*$A9*(1-E$3/E$1*$A9)) -> 0.9665774 | F9: =+$A9/$G$1 -> 0.032 | G9: =+SQRT(1-G$2/G$1*$A9*(1-G$3/G$1*$A9)) -> 0.95734165
A10: =+$A9+$A$3 -> 0.5 | B10: =+$A10/$C$1 -> 0.019230769 | C10: =+SQRT(1-C$2/C$1*$A10*(1-C$3/C$1*$A10)) -> 0.97423066 | D10: =+$A10/$E$1 -> 0.03125 | E10: =+SQRT(1-E$2/E$1*$A10*(1-E$3/E$1*$A10)) -> 0.95832852 | F10: =+$A10/$G$1 -> 0.04 | G10: =+SQRT(1-G$2/G$1*$A10*(1-G$3/G$1*$A10)) -> 0.94685585
A11: =+$A10+$A$3 -> 0.6 | B11: =+$A11/$C$1 -> 0.023076923 | C11: =+SQRT(1-C$2/C$1*$A11*(1-C$3/C$1*$A11)) -> 0.96912438 | D11: =+$A11/$E$1 -> 0.0375 | E11: =+SQRT(1-E$2/E$1*$A11*(1-E$3/E$1*$A11)) -> 0.95012458 | F11: =+$A11/$G$1 -> 0.048 | G11: =+SQRT(1-G$2/G$1*$A11*(1-G$3/G$1*$A11)) -> 0.93644639
A12: =+$A11+$A$3 -> 0.7 | B12: =+$A12/$C$1 -> 0.026923077 | C12: =+SQRT(1-C$2/C$1*$A12*(1-C$3/C$1*$A12)) -> 0.96403457 | D12: =+$A12/$E$1 -> 0.04375 | E12: =+SQRT(1-E$2/E$1*$A12*(1-E$3/E$1*$A12)) -> 0.94196675 | F12: =+$A12/$G$1 -> 0.056 | G12: =+SQRT(1-G$2/G$1*$A12*(1-G$3/G$1*$A12)) -> 0.92611585
A13: =+$A12+$A$3 -> 0.8 | B13: =+$A13/$C$1 -> 0.030769231 | C13: =+SQRT(1-C$2/C$1*$A13*(1-C$3/C$1*$A13)) -> 0.95896147 | D13: =+$A13/$E$1 -> 0.05 | E13: =+SQRT(1-E$2/E$1*$A13*(1-E$3/E$1*$A13)) -> 0.93385625 | F13: =+$A13/$G$1 -> 0.064 | G13: =+SQRT(1-G$2/G$1*$A13*(1-G$3/G$1*$A13)) -> 0.91586689
A14: =+$A13+$A$3 -> 0.9 | B14: =+$A14/$C$1 -> 0.034615385 | C14: =+SQRT(1-C$2/C$1*$A14*(1-C$3/C$1*$A14)) -> 0.95390536 | D14: =+$A14/$E$1 -> 0.05625 | E14: =+SQRT(1-E$2/E$1*$A14*(1-E$3/E$1*$A14)) -> 0.92579432 | F14: =+$A14/$G$1 -> 0.072 | G14: =+SQRT(1-G$2/G$1*$A14*(1-G$3/G$1*$A14)) -> 0.90570229
A15: =+$A14+$A$3 -> 1 | B15: =+$A15/$C$1 -> 0.038461538 | C15: =+SQRT(1-C$2/C$1*$A15*(1-C$3/C$1*$A15)) -> 0.9488665 | D15: =+$A15/$E$1 -> 0.0625 | E15: =+SQRT(1-E$2/E$1*$A15*(1-E$3/E$1*$A15)) -> 0.91778223 | F15: =+$A15/$G$1 -> 0.08 | G15: =+SQRT(1-G$2/G$1*$A15*(1-G$3/G$1*$A15)) -> 0.89562492
A16: =+$A15+$A$3 -> 1.1 | B16: =+$A16/$C$1 -> 0.042307692 | C16: =+SQRT(1-C$2/C$1*$A16*(1-C$3/C$1*$A16)) -> 0.94384517 | D16: =+$A16/$E$1 -> 0.06875 | E16: =+SQRT(1-E$2/E$1*$A16*(1-E$3/E$1*$A16)) -> 0.9098213 | F16: =+$A16/$G$1 -> 0.088 | G16: =+SQRT(1-G$2/G$1*$A16*(1-G$3/G$1*$A16)) -> 0.88563776
A17: =+$A16+$A$3 -> 1.2 | B17: =+$A17/$C$1 -> 0.046153846 | C17: =+SQRT(1-C$2/C$1*$A17*(1-C$3/C$1*$A17)) -> 0.93884166 | D17: =+$A17/$E$1 -> 0.075 | E17: =+SQRT(1-E$2/E$1*$A17*(1-E$3/E$1*$A17)) -> 0.9019129 | F17: =+$A17/$G$1 -> 0.096 | G17: =+SQRT(1-G$2/G$1*$A17*(1-G$3/G$1*$A17)) -> 0.87574389
... A85: =+$A84+$A$3 -> 8 | B85: =+$A85/$C$1 -> 0.30769231 | C85: =+SQRT(1-C$2/C$1*$A85*(1-C$3/C$1*$A85)) -> 0.66153846 | D85: =+$A85/$E$1 -> 0.5 | E85: =+SQRT(1-E$2/E$1*$A85*(1-E$3/E$1*$A85)) -> 0.59895743 | F85: =+$A85/$G$1 -> 0.64 | G85: =+SQRT(1-G$2/G$1*$A85*(1-G$3/G$1*$A85)) -> 0.65819146
A86: =+$A85+$A$3 -> 8.1 | B86: =+$A86/$C$1 -> 0.31153846 | C86: =+SQRT(1-C$2/C$1*$A86*(1-C$3/C$1*$A86)) -> 0.65878716 | D86: =+$A86/$E$1 -> 0.50625 | E86: =+SQRT(1-E$2/E$1*$A86*(1-E$3/E$1*$A86)) -> 0.59975369
A87: =+$A86+$A$3 -> 8.2 | B87: =+$A87/$C$1 -> 0.31538462 | C87: =+SQRT(1-C$2/C$1*$A87*(1-C$3/C$1*$A87)) -> 0.65608824 | D87: =+$A87/$E$1 -> 0.5125 | E87: =+SQRT(1-E$2/E$1*$A87*(1-E$3/E$1*$A87)) -> 0.60073328
A88: =+$A87+$A$3 -> 8.3 | B88: =+$A88/$C$1 -> 0.31923077 | C88: =+SQRT(1-C$2/C$1*$A88*(1-C$3/C$1*$A88)) -> 0.65344235 | D88: =+$A88/$E$1 -> 0.51875 | E88: =+SQRT(1-E$2/E$1*$A88*(1-E$3/E$1*$A88)) -> 0.60189528
A89: =+$A88+$A$3 -> 8.4 | B89: =+$A89/$C$1 -> 0.32307692 | C89: =+SQRT(1-C$2/C$1*$A89*(1-C$3/C$1*$A89)) -> 0.65085015 | D89: =+$A89/$E$1 -> 0.525 | E89: =+SQRT(1-E$2/E$1*$A89*(1-E$3/E$1*$A89)) -> 0.60323866
A90: =+$A89+$A$3 -> 8.5 | B90: =+$A90/$C$1 -> 0.32692308 | C90: =+SQRT(1-C$2/C$1*$A90*(1-C$3/C$1*$A90)) -> 0.64831227 | D90: =+$A90/$E$1 -> 0.53125 | E90: =+SQRT(1-E$2/E$1*$A90*(1-E$3/E$1*$A90)) -> 0.60476219
A91: =+$A90+$A$3 -> 8.6 | B91: =+$A91/$C$1 -> 0.33076923 | C91: =+SQRT(1-C$2/C$1*$A91*(1-C$3/C$1*$A91)) -> 0.64582936 | D91: =+$A91/$E$1 -> 0.5375 | E91: =+SQRT(1-E$2/E$1*$A91*(1-E$3/E$1*$A91)) -> 0.60646452
A92: =+$A91+$A$3 -> 8.7 | B92: =+$A92/$C$1 -> 0.33461538 | C92: =+SQRT(1-C$2/C$1*$A92*(1-C$3/C$1*$A92)) -> 0.64340205 | D92: =+$A92/$E$1 -> 0.54375 | E92: =+SQRT(1-E$2/E$1*$A92*(1-E$3/E$1*$A92)) -> 0.60834416
A93: =+$A92+$A$3 -> 8.8 | B93: =+$A93/$C$1 -> 0.33846154 | C93: =+SQRT(1-C$2/C$1*$A93*(1-C$3/C$1*$A93)) -> 0.64103097 | D93: =+$A93/$E$1 -> 0.55 | E93: =+SQRT(1-E$2/E$1*$A93*(1-E$3/E$1*$A93)) -> 0.61039946
A94: =+$A93+$A$3 -> 8.9 | B94: =+$A94/$C$1 -> 0.34230769 | C94: =+SQRT(1-C$2/C$1*$A94*(1-C$3/C$1*$A94)) -> 0.63871676 | D94: =+$A94/$E$1 -> 0.55625 | E94: =+SQRT(1-E$2/E$1*$A94*(1-E$3/E$1*$A94)) -> 0.61262865
A95: =+$A94+$A$3 -> 9 | B95: =+$A95/$C$1 -> 0.34615385 | C95: =+SQRT(1-C$2/C$1*$A95*(1-C$3/C$1*$A95)) -> 0.63646002 | D95: =+$A95/$E$1 -> 0.5625 | E95: =+SQRT(1-E$2/E$1*$A95*(1-E$3/E$1*$A95)) -> 0.61502985
A96: =+$A95+$A$3 -> 9.1 | B96: =+$A96/$C$1 -> 0.35 | C96: =+SQRT(1-C$2/C$1*$A96*(1-C$3/C$1*$A96)) -> 0.63426138 | D96: =+$A96/$E$1 -> 0.56875 | E96: =+SQRT(1-E$2/E$1*$A96*(1-E$3/E$1*$A96)) -> 0.61760105
A97: =+$A96+$A$3 -> 9.2 | B97: =+$A97/$C$1 -> 0.35384615 | C97: =+SQRT(1-C$2/C$1*$A97*(1-C$3/C$1*$A97)) -> 0.63212144 | D97: =+$A97/$E$1 -> 0.575 | E97: =+SQRT(1-E$2/E$1*$A97*(1-E$3/E$1*$A97)) -> 0.62034013
... A115: =+$A114+$A$3 -> 11 | B115: =+$A115/$C$1 -> 0.42307692 | C115: =+SQRT(1-C$2/C$1*$A115*(1-C$3/C$1*$A115)) -> 0.60426859 | D115: =+$A115/$E$1 -> 0.6875 | E115: =+SQRT(1-E$2/E$1*$A115*(1-E$3/E$1*$A115)) -> 0.69550735
A116: =+$A115+$A$3 -> 11.1 | B116: =+$A116/$C$1 -> 0.42692308 | C116: =+SQRT(1-C$2/C$1*$A116*(1-C$3/C$1*$A116)) -> 0.60334417
A117: =+$A116+$A$3 -> 11.2 | B117: =+$A117/$C$1 -> 0.43076923 | C117: =+SQRT(1-C$2/C$1*$A117*(1-C$3/C$1*$A117)) -> 0.60248794
A118: =+$A117+$A$3 -> 11.3 | B118: =+$A118/$C$1 -> 0.43461538 | C118: =+SQRT(1-C$2/C$1*$A118*(1-C$3/C$1*$A118)) -> 0.60170019
A119: =+$A118+$A$3 -> 11.4 | B119: =+$A119/$C$1 -> 0.43846154 | C119: =+SQRT(1-C$2/C$1*$A119*(1-C$3/C$1*$A119)) -> 0.6009812
A120: =+$A119+$A$3 -> 11.5 | B120: =+$A120/$C$1 -> 0.44230769 | C120: =+SQRT(1-C$2/C$1*$A120*(1-C$3/C$1*$A120)) -> 0.60033121
A121: =+$A120+$A$3 -> 11.6 | B121: =+$A121/$C$1 -> 0.44615385 | C121: =+SQRT(1-C$2/C$1*$A121*(1-C$3/C$1*$A121)) -> 0.59975044
A122: =+$A121+$A$3 -> 11.7 | B122: =+$A122/$C$1 -> 0.45 | C122: =+SQRT(1-C$2/C$1*$A122*(1-C$3/C$1*$A122)) -> 0.5992391
A123: =+$A122+$A$3 -> 11.8 | B123: =+$A123/$C$1 -> 0.45384615 | C123: =+SQRT(1-C$2/C$1*$A123*(1-C$3/C$1*$A123)) -> 0.59879736
A124: =+$A123+$A$3 -> 11.9 | B124: =+$A124/$C$1 -> 0.45769231 | C124: =+SQRT(1-C$2/C$1*$A124*(1-C$3/C$1*$A124)) -> 0.59842539
...
